Workbook

Sheet Question
A1: 9 | B1: 7 | C1: 2 | D1: 9 | E1: 5 | F1: 6 | G1: 6 | H1: 7 | I1: 3 | J1: 6 | K1: 4 | L1: 8 | M1: 3 | N1: 9 | O1: 9 | P1: 5 | Q1: 4 | R1: 4 | S1: 9 | T1: 2 | U1: 2 | V1: 6 | W1: 8 | X1: 5 | Y1: 5 | Z1: 7 | AA1: 8 | AB1: 9 | AC1: 3 | AD1: 3 | AE1: 4 | AF1: 0 | AG1: 8 | AH1: 2 | AI1: 7 | AJ1: 4 | AK1: 3 | AL1: 6 | AM1: 5 | AN1: 9 | AO1: 5 | AP1: 8 | AQ1: 6 | AR1: 4 | AS1: 9 | AT1: 3 | AU1: 4 | AV1: 6 | AW1: 7 | AX1: 9 | AY1: 6 | AZ1: 9 | BA1: 2 | BB1: 7 | BC1: 5 | BD1: 9 | BE1: 6 | BF1: 6 | BG1: 3 | BH1: 7 | BI1: 6 | BK1: =CONCATENATE(A1,B1,C1,D1,E1,F1,G1,H1,I1,J1,K1,L1,M1,N1,O1,P1,Q1,R1,S1,T1,U1,V1,W1,X1,Y1,Z1,AA1,AB1,AC1,AD1,AE1,AF1,AG1,AH1,AI1,AJ1,AK1,AL1,AM1,AN1,AO1,AP1,AQ1,AR1,AS1,AT1,AU1,AV1,AW1,AX1,AY1,AZ1,BA1,BB1,BC1,BD1,BE1,BF1,BG1,BH1,BI1) -> 9729566736483995449226855789334082743659586493467969275966376 | BL1: =CONCATENATE(A1,B1,C1,D1,E1,F1,G1,H1,I1,J1,K1,L1,M1,N1,O1,P1,Q1,R1,S1,T1,U1,V1,W1,X1,Y1,Z1,AA1,AB1,AC1,AD1,AE1,AF1,AG1,AH1,AI1,AJ1,AK1,AL1,AM1,AN1,AO1,AP1,AQ1,AR1,AS1,AT1,AU1,AV1,AW1,AX1,AY1,AZ1,BA1,BB1,BC1,BD1) -> 97295667364839954492268557893340827436595864934679692759 | BM1: ="["&A1&","&B1&","&C1&","&D1&","&E1&","&F1&","&G1&","&H1&","&I1&","&J1&","&K1&","&L1&","&M1&","&N1&","&O1&","&P1&","&Q1&","&R1&","&S1&","&T1&","&U1&","&V1&","&W1&","&X1&","&Y1&","&Z1&","&AA1&","&AB1&","&AC1&","&AD1&","&AE1&","&AF1&","&AG1&","&AH1&","&AI1&","&AJ1&","&AK1&","&AL1&","&AM1&","&AN1&","&AO1&","&AP1&","&AQ1&","&AR1&","&AS1&","&AT1&","&AU1&","&AV1&","&AW1&","&AX1&","&AY1&","&AZ1&","&BA1&","&BB1&","&BC1&","&BD1&"]," -> [9,7,2,9,5,6,6,7,3,6,4,8,3,9,9,5,4,4,9,2,2,6,8,5,5,7,8,9,3,3,4,0,8,2,7,4,3,6,5,9,5,8,6,4,9,3,4,6,7,9,6,9,2,7,5,9], | BW1: =MOD(A1+B1,10) -> 6 | BX1: =MOD(B1+C1,10) -> 9 | BY1: =MOD(C1+D1,10) -> 1 | BZ1: =MOD(D1+E1,10) -> 4 | CA1: =MOD(E1+F1,10) -> 1 | CB1: =MOD(F1+G1,10) -> 2 | CC1: =MOD(G1+H1,10) -> 3 | CD1: =MOD(H1+I1,10) -> 0 | ... DY1: =MOD(BC1+BD1,10) -> 4 | DZ1: ="["&BW1&","&BX1&","&BY1&","&BZ1&","&CA1&","&CB1&","&CC1&","&CD1&","&CE1&","&CF1&","&CG1&","&CH1&","&CI1&","&CJ1&","&CK1&","&CL1&","&CM1&","&CN1&","&CO1&","&CP1&","&CQ1&","&CR1&","&CS1&","&CT1&","&CU1&","&CV1&","&CW1&","&CX1&","&CY1&","&CZ1&","&DA1&","&DB1&","&DC1&","&DD1&","&DE1&","&DF1&","&DG1&","&DH1&","&DI1&","&DJ1&","&DK1&","&DL1&","&DM1&","&DN1&","&DO1&","&DP1&","&DQ1&","&DR1&","&DS1&","&DT1&","&DU1&","&DV1&","&DW1&","&DX1&","&DY1&"]," -> [6,9,1,4,1,2,3,0,9,0,2,1,2,8,4,9,8,3,1,4,8,4,3,0,2,5,7,2,6,7,4,8,0,9,1,7,9,1,4,4,3,4,0,3,2,7,0,3,6,5,5,1,9,2,4],
A2: 9 | B2: 9 | C2: 8 | D2: 4 | E2: 4 | F2: 6 | G2: 5 | H2: 2 | I2: 7 | J2: 7 | K2: 8 | L2: 9 | M2: 3 | N2: 3 | O2: 7 | P2: 1 | Q2: 6 | R2: 2 | S2: 5 | T2: 7 | U2: 9 | V2: 4 | W2: 2 | X2: 8 | Y2: 2 | Z2: 7 | AA2: 7 | AB2: 3 | AC2: 5 | AD2: 2 | AE2: 3 | AF2: 2 | AG2: 4 | AH2: 7 | AI2: 5 | AJ2: 8 | AK2: 6 | AL2: 9 | AM2: 8 | AN2: 4 | AO2: 5 | AP2: 3 | AQ2: 7 | AR2: 4 | AS2: 6 | AT2: 3 | AU2: 8 | AV2: 8 | AW2: 7 | AX2: 6 | AY2: 5 | AZ2: 9 | BA2: 8 | BB2: 9 | BC2: 4 | BD2: 4 | BE2: 5 | BF2: 6 | BG2: 7 | BH2: 2 | BI2: 7 | BK2: =CONCATENATE(A2,B2,C2,D2,E2,F2,G2,H2,I2,J2,K2,L2,M2,N2,O2,P2,Q2,R2,S2,T2,U2,V2,W2,X2,Y2,Z2,AA2,AB2,AC2,AD2,AE2,AF2,AG2,AH2,AI2,AJ2,AK2,AL2,AM2,AN2,AO2,AP2,AQ2,AR2,AS2,AT2,AU2,AV2,AW2,AX2,AY2,AZ2,BA2,BB2,BC2,BD2,BE2,BF2,BG2,BH2,BI2) -> 9984465277893371625794282773523247586984537463887659894456727 | BL2: =CONCATENATE(A2,B2,C2,D2,E2,F2,G2,H2,I2,J2,K2,L2,M2,N2,O2,P2,Q2,R2,S2,T2,U2,V2,W2,X2,Y2,Z2,AA2,AB2,AC2,AD2,AE2,AF2,AG2,AH2,AI2,AJ2,AK2,AL2,AM2,AN2,AO2,AP2,AQ2,AR2,AS2,AT2,AU2,AV2,AW2,AX2,AY2,AZ2,BA2,BB2,BC2,BD2) -> 99844652778933716257942827735232475869845374638876598944 | BM2: ="["&A2&","&B2&","&C2&","&D2&","&E2&","&F2&","&G2&","&H2&","&I2&","&J2&","&K2&","&L2&","&M2&","&N2&","&O2&","&P2&","&Q2&","&R2&","&S2&","&T2&","&U2&","&V2&","&W2&","&X2&","&Y2&","&Z2&","&AA2&","&AB2&","&AC2&","&AD2&","&AE2&","&AF2&","&AG2&","&AH2&","&AI2&","&AJ2&","&AK2&","&AL2&","&AM2&","&AN2&","&AO2&","&AP2&","&AQ2&","&AR2&","&AS2&","&AT2&","&AU2&","&AV2&","&AW2&","&AX2&","&AY2&","&AZ2&","&BA2&","&BB2&","&BC2&","&BD2&"]," -> [9,9,8,4,4,6,5,2,7,7,8,9,3,3,7,1,6,2,5,7,9,4,2,8,2,7,7,3,5,2,3,2,4,7,5,8,6,9,8,4,5,3,7,4,6,3,8,8,7,6,5,9,8,9,4,4], | BW2: =MOD(A2+B2,10) -> 8 | BX2: =MOD(B2+C2,10) -> 7 | BY2: =MOD(C2+D2,10) -> 2 | BZ2: =MOD(D2+E2,10) -> 8 | CA2: =MOD(E2+F2,10) -> 0 | CB2: =MOD(F2+G2,10) -> 1 | CC2: =MOD(G2+H2,10) -> 7 | CD2: =MOD(H2+I2,10) -> 9 | ... DY2: =MOD(BC2+BD2,10) -> 8 | DZ2: ="["&BW2&","&BX2&","&BY2&","&BZ2&","&CA2&","&CB2&","&CC2&","&CD2&","&CE2&","&CF2&","&CG2&","&CH2&","&CI2&","&CJ2&","&CK2&","&CL2&","&CM2&","&CN2&","&CO2&","&CP2&","&CQ2&","&CR2&","&CS2&","&CT2&","&CU2&","&CV2&","&CW2&","&CX2&","&CY2&","&CZ2&","&DA2&","&DB2&","&DC2&","&DD2&","&DE2&","&DF2&","&DG2&","&DH2&","&DI2&","&DJ2&","&DK2&","&DL2&","&DM2&","&DN2&","&DO2&","&DP2&","&DQ2&","&DR2&","&DS2&","&DT2&","&DU2&","&DV2&","&DW2&","&DX2&","&DY2&"]," -> [8,7,2,8,0,1,7,9,4,5,7,2,6,0,8,7,8,7,2,6,3,6,0,0,9,4,0,8,7,5,5,6,1,2,3,4,5,7,2,9,8,0,1,0,9,1,6,5,3,1,4,7,7,3,8],
A3: 0 | B3: 3 | C3: 6 | D3: 8 | E3: 3 | F3: 4 | G3: 5 | H3: 7 | I3: 6 | J3: 3 | K3: 5 | L3: 9 | M3: 4 | N3: 2 | O3: 4 | P3: 7 | Q3: 9 | R3: 2 | S3: 5 | T3: 6 | U3: 7 | V3: 4 | W3: 3 | X3: 2 | Y3: 6 | Z3: 9 | AA3: 5 | AB3: 8 | AC3: 8 | AD3: 7 | AE3: 5 | AF3: 3 | AG3: 8 | AH3: 6 | AI3: 6 | AJ3: 4 | AK3: 9 | AL3: 7 | AM3: 2 | AN3: 8 | AO3: 5 | AP3: 5 | AQ3: 4 | AR3: 8 | AS3: 3 | AT3: 9 | AU3: 9 | AV3: 6 | AW3: 8 | AX3: 2 | AY3: 2 | AZ3: 0 | BA3: 6 | BB3: 3 | BC3: 3 | BD3: 8 | BE3: 5 | BF3: 4 | BG3: 6 | BH3: 7 | BI3: 3 | BK3: =CONCATENATE(A3,B3,C3,D3,E3,F3,G3,H3,I3,J3,K3,L3,M3,N3,O3,P3,Q3,R3,S3,T3,U3,V3,W3,X3,Y3,Z3,AA3,AB3,AC3,AD3,AE3,AF3,AG3,AH3,AI3,AJ3,AK3,AL3,AM3,AN3,AO3,AP3,AQ3,AR3,AS3,AT3,AU3,AV3,AW3,AX3,AY3,AZ3,BA3,BB3,BC3,BD3,BE3,BF3,BG3,BH3,BI3) -> 0368345763594247925674326958875386649728554839968220633854673 | BL3: =CONCATENATE(A3,B3,C3,D3,E3,F3,G3,H3,I3,J3,K3,L3,M3,N3,O3,P3,Q3,R3,S3,T3,U3,V3,W3,X3,Y3,Z3,AA3,AB3,AC3,AD3,AE3,AF3,AG3,AH3,AI3,AJ3,AK3,AL3,AM3,AN3,AO3,AP3,AQ3,AR3,AS3,AT3,AU3,AV3,AW3,AX3,AY3,AZ3,BA3,BB3,BC3,BD3) -> 03683457635942479256743269588753866497285548399682206338 | BM3: ="["&A3&","&B3&","&C3&","&D3&","&E3&","&F3&","&G3&","&H3&","&I3&","&J3&","&K3&","&L3&","&M3&","&N3&","&O3&","&P3&","&Q3&","&R3&","&S3&","&T3&","&U3&","&V3&","&W3&","&X3&","&Y3&","&Z3&","&AA3&","&AB3&","&AC3&","&AD3&","&AE3&","&AF3&","&AG3&","&AH3&","&AI3&","&AJ3&","&AK3&","&AL3&","&AM3&","&AN3&","&AO3&","&AP3&","&AQ3&","&AR3&","&AS3&","&AT3&","&AU3&","&AV3&","&AW3&","&AX3&","&AY3&","&AZ3&","&BA3&","&BB3&","&BC3&","&BD3&"]," -> [0,3,6,8,3,4,5,7,6,3,5,9,4,2,4,7,9,2,5,6,7,4,3,2,6,9,5,8,8,7,5,3,8,6,6,4,9,7,2,8,5,5,4,8,3,9,9,6,8,2,2,0,6,3,3,8], | BW3: =MOD(A3+B3,10) -> 3 | BX3: =MOD(B3+C3,10) -> 9 | BY3: =MOD(C3+D3,10) -> 4 | BZ3: =MOD(D3+E3,10) -> 1 | CA3: =MOD(E3+F3,10) -> 7 | CB3: =MOD(F3+G3,10) -> 9 | CC3: =MOD(G3+H3,10) -> 2 | CD3: =MOD(H3+I3,10) -> 3 | ... DY3: =MOD(BC3+BD3,10) -> 1 | DZ3: ="["&BW3&","&BX3&","&BY3&","&BZ3&","&CA3&","&CB3&","&CC3&","&CD3&","&CE3&","&CF3&","&CG3&","&CH3&","&CI3&","&CJ3&","&CK3&","&CL3&","&CM3&","&CN3&","&CO3&","&CP3&","&CQ3&","&CR3&","&CS3&","&CT3&","&CU3&","&CV3&","&CW3&","&CX3&","&CY3&","&CZ3&","&DA3&","&DB3&","&DC3&","&DD3&","&DE3&","&DF3&","&DG3&","&DH3&","&DI3&","&DJ3&","&DK3&","&DL3&","&DM3&","&DN3&","&DO3&","&DP3&","&DQ3&","&DR3&","&DS3&","&DT3&","&DU3&","&DV3&","&DW3&","&DX3&","&DY3&"]," -> [3,9,4,1,7,9,2,3,9,8,4,3,6,6,1,6,1,7,1,3,1,7,5,8,5,4,3,6,5,2,8,1,4,2,0,3,6,9,0,3,0,9,2,1,2,8,5,4,0,4,2,6,9,6,1],
A4: 4 | B4: 2 | C4: 6 | D4: 4 | E4: 3 | F4: 7 | G4: 9 | H4: 6 | I4: 5 | J4: 4 | K4: 8 | L4: 6 | M4: 7 | N4: 7 | O4: 2 | P4: 3 | Q4: 3 | R4: 4 | S4: 9 | T4: 5 | U4: 2 | V4: 7 | W4: 6 | X4: 8 | Y4: 8 | Z4: 9 | AA4: 2 | AB4: 4 | AC4: 5 | AD4: 3 | AE4: 9 | AF4: 8 | AG4: 5 | AH4: 5 | AI4: 6 | AJ4: 3 | AK4: 2 | AL4: 9 | AM4: 4 | AN4: 4 | AO4: 6 | AP4: 2 | AQ4: 2 | AR4: 8 | AS4: 7 | AT4: 5 | AU4: 9 | AV4: 9 | AW4: 7 | AX4: 3 | AY4: 8 | AZ4: 4 | BA4: 6 | BB4: 2 | BC4: 3 | BD4: 4 | BE4: 9 | BF4: 7 | BG4: 5 | BH4: 6 | BI4: 4 | BK4: =CONCATENATE(A4,B4,C4,D4,E4,F4,G4,H4,I4,J4,K4,L4,M4,N4,O4,P4,Q4,R4,S4,T4,U4,V4,W4,X4,Y4,Z4,AA4,AB4,AC4,AD4,AE4,AF4,AG4,AH4,AI4,AJ4,AK4,AL4,AM4,AN4,AO4,AP4,AQ4,AR4,AS4,AT4,AU4,AV4,AW4,AX4,AY4,AZ4,BA4,BB4,BC4,BD4,BE4,BF4,BG4,BH4,BI4) -> 4264379654867723349527688924539855632944622875997384623497564 | BL4: =CONCATENATE(A4,B4,C4,D4,E4,F4,G4,H4,I4,J4,K4,L4,M4,N4,O4,P4,Q4,R4,S4,T4,U4,V4,W4,X4,Y4,Z4,AA4,AB4,AC4,AD4,AE4,AF4,AG4,AH4,AI4,AJ4,AK4,AL4,AM4,AN4,AO4,AP4,AQ4,AR4,AS4,AT4,AU4,AV4,AW4,AX4,AY4,AZ4,BA4,BB4,BC4,BD4) -> 42643796548677233495276889245398556329446228759973846234 | BM4: ="["&A4&","&B4&","&C4&","&D4&","&E4&","&F4&","&G4&","&H4&","&I4&","&J4&","&K4&","&L4&","&M4&","&N4&","&O4&","&P4&","&Q4&","&R4&","&S4&","&T4&","&U4&","&V4&","&W4&","&X4&","&Y4&","&Z4&","&AA4&","&AB4&","&AC4&","&AD4&","&AE4&","&AF4&","&AG4&","&AH4&","&AI4&","&AJ4&","&AK4&","&AL4&","&AM4&","&AN4&","&AO4&","&AP4&","&AQ4&","&AR4&","&AS4&","&AT4&","&AU4&","&AV4&","&AW4&","&AX4&","&AY4&","&AZ4&","&BA4&","&BB4&","&BC4&","&BD4&"]," -> [4,2,6,4,3,7,9,6,5,4,8,6,7,7,2,3,3,4,9,5,2,7,6,8,8,9,2,4,5,3,9,8,5,5,6,3,2,9,4,4,6,2,2,8,7,5,9,9,7,3,8,4,6,2,3,4], | BW4: =MOD(A4+B4,10) -> 6 | BX4: =MOD(B4+C4,10) -> 8 | BY4: =MOD(C4+D4,10) -> 0 | BZ4: =MOD(D4+E4,10) -> 7 | CA4: =MOD(E4+F4,10) -> 0 | CB4: =MOD(F4+G4,10) -> 6 | CC4: =MOD(G4+H4,10) -> 5 | CD4: =MOD(H4+I4,10) -> 1 | ... DY4: =MOD(BC4+BD4,10) -> 7 | DZ4: ="["&BW4&","&BX4&","&BY4&","&BZ4&","&CA4&","&CB4&","&CC4&","&CD4&","&CE4&","&CF4&","&CG4&","&CH4&","&CI4&","&CJ4&","&CK4&","&CL4&","&CM4&","&CN4&","&CO4&","&CP4&","&CQ4&","&CR4&","&CS4&","&CT4&","&CU4&","&CV4&","&CW4&","&CX4&","&CY4&","&CZ4&","&DA4&","&DB4&","&DC4&","&DD4&","&DE4&","&DF4&","&DG4&","&DH4&","&DI4&","&DJ4&","&DK4&","&DL4&","&DM4&","&DN4&","&DO4&","&DP4&","&DQ4&","&DR4&","&DS4&","&DT4&","&DU4&","&DV4&","&DW4&","&DX4&","&DY4&"]," -> [6,8,0,7,0,6,5,1,9,2,4,3,4,9,5,6,7,3,4,7,9,3,4,6,7,1,6,9,8,2,7,3,0,1,9,5,1,3,8,0,8,4,0,5,2,4,8,6,0,1,2,0,8,5,7],
A5: 6 | B5: 2 | C5: 7 | D5: 9 | E5: 5 | F5: 5 | G5: 7 | H5: 8 | I5: 5 | J5: 4 | K5: 9 | L5: 7 | M5: 7 | N5: 2 | O5: 4 | P5: 3 | Q5: 8 | R5: 6 | S5: 9 | T5: 2 | U5: 2 | V5: 8 | W5: 7 | X5: 3 | Y5: 9 | Z5: 4 | AA5: 4 | AB5: 5 | AC5: 6 | AD5: 6 | AE5: 3 | AF5: 2 | AG5: 9 | AH5: 8 | AI5: 8 | AJ5: 3 | AK5: 5 | AL5: 1 | AM5: 7 | AN5: 8 | AO5: 2 | AP5: 5 | AQ5: 3 | AR5: 6 | AS5: 6 | AT5: 9 | AU5: 3 | AV5: 5 | AW5: 8 | AX5: 4 | AY5: 7 | AZ5: 6 | BA5: 7 | BB5: 2 | BC5: 5 | BD5: 9 | BE5: 7 | BF5: 5 | BG5: 5 | BH5: 8 | BI5: 4 | BK5: =CONCATENATE(A5,B5,C5,D5,E5,F5,G5,H5,I5,J5,K5,L5,M5,N5,O5,P5,Q5,R5,S5,T5,U5,V5,W5,X5,Y5,Z5,AA5,AB5,AC5,AD5,AE5,AF5,AG5,AH5,AI5,AJ5,AK5,AL5,AM5,AN5,AO5,AP5,AQ5,AR5,AS5,AT5,AU5,AV5,AW5,AX5,AY5,AZ5,BA5,BB5,BC5,BD5,BE5,BF5,BG5,BH5,BI5) -> 6279557854977243869228739445663298835178253669358476725975584 | BL5: =CONCATENATE(A5,B5,C5,D5,E5,F5,G5,H5,I5,J5,K5,L5,M5,N5,O5,P5,Q5,R5,S5,T5,U5,V5,W5,X5,Y5,Z5,AA5,AB5,AC5,AD5,AE5,AF5,AG5,AH5,AI5,AJ5,AK5,AL5,AM5,AN5,AO5,AP5,AQ5,AR5,AS5,AT5,AU5,AV5,AW5,AX5,AY5,AZ5,BA5,BB5,BC5,BD5) -> 62795578549772438692287394456632988351782536693584767259 | BM5: ="["&A5&","&B5&","&C5&","&D5&","&E5&","&F5&","&G5&","&H5&","&I5&","&J5&","&K5&","&L5&","&M5&","&N5&","&O5&","&P5&","&Q5&","&R5&","&S5&","&T5&","&U5&","&V5&","&W5&","&X5&","&Y5&","&Z5&","&AA5&","&AB5&","&AC5&","&AD5&","&AE5&","&AF5&","&AG5&","&AH5&","&AI5&","&AJ5&","&AK5&","&AL5&","&AM5&","&AN5&","&AO5&","&AP5&","&AQ5&","&AR5&","&AS5&","&AT5&","&AU5&","&AV5&","&AW5&","&AX5&","&AY5&","&AZ5&","&BA5&","&BB5&","&BC5&","&BD5&"]," -> [6,2,7,9,5,5,7,8,5,4,9,7,7,2,4,3,8,6,9,2,2,8,7,3,9,4,4,5,6,6,3,2,9,8,8,3,5,1,7,8,2,5,3,6,6,9,3,5,8,4,7,6,7,2,5,9], | BW5: =MOD(A5+B5,10) -> 8 | BX5: =MOD(B5+C5,10) -> 9 | BY5: =MOD(C5+D5,10) -> 6 | BZ5: =MOD(D5+E5,10) -> 4 | CA5: =MOD(E5+F5,10) -> 0 | CB5: =MOD(F5+G5,10) -> 2 | CC5: =MOD(G5+H5,10) -> 5 | CD5: =MOD(H5+I5,10) -> 3 | ... DY5: =MOD(BC5+BD5,10) -> 4 | DZ5: ="["&BW5&","&BX5&","&BY5&","&BZ5&","&CA5&","&CB5&","&CC5&","&CD5&","&CE5&","&CF5&","&CG5&","&CH5&","&CI5&","&CJ5&","&CK5&","&CL5&","&CM5&","&CN5&","&CO5&","&CP5&","&CQ5&","&CR5&","&CS5&","&CT5&","&CU5&","&CV5&","&CW5&","&CX5&","&CY5&","&CZ5&","&DA5&","&DB5&","&DC5&","&DD5&","&DE5&","&DF5&","&DG5&","&DH5&","&DI5&","&DJ5&","&DK5&","&DL5&","&DM5&","&DN5&","&DO5&","&DP5&","&DQ5&","&DR5&","&DS5&","&DT5&","&DU5&","&DV5&","&DW5&","&DX5&","&DY5&"]," -> [8,9,6,4,0,2,5,3,9,3,6,4,9,6,7,1,4,5,1,4,0,5,0,2,3,8,9,1,2,9,5,1,7,6,1,8,6,8,5,0,7,8,9,2,5,2,8,3,2,1,3,3,9,7,4],
A6: 8 | B6: 8 | C6: 4 | D6: 5 | E6: 3 | F6: 8 | G6: 7 | H6: 7 | I6: 2 | J6: 9 | K6: 6 | L6: 5 | M6: 4 | N6: 4 | O6: 7 | P6: 6 | Q6: 2 | R6: 8 | S6: 9 | T6: 9 | U6: 3 | V6: 2 | W6: 0 | X6: 2 | Y6: 5 | Z6: 2 | AA6: 3 | AB6: 6 | AC6: 4 | AD6: 8 | AE6: 2 | AF6: 6 | AG6: 7 | AH6: 4 | AI6: 6 | AJ6: 5 | AK6: 9 | AL6: 6 | AM6: 8 | AN6: 9 | AO6: 9 | AP6: 3 | AQ6: 4 | AR6: 7 | AS6: 5 | AT6: 8 | AU6: 4 | AV6: 2 | AW6: 3 | AX6: 3 | AY6: 7 | AZ6: 8 | BA6: 4 | BB6: 8 | BC6: 3 | BD6: 5 | BE6: 7 | BF6: 8 | BG6: 2 | BH6: 7 | BI6: 9 | BK6: =CONCATENATE(A6,B6,C6,D6,E6,F6,G6,H6,I6,J6,K6,L6,M6,N6,O6,P6,Q6,R6,S6,T6,U6,V6,W6,X6,Y6,Z6,AA6,AB6,AC6,AD6,AE6,AF6,AG6,AH6,AI6,AJ6,AK6,AL6,AM6,AN6,AO6,AP6,AQ6,AR6,AS6,AT6,AU6,AV6,AW6,AX6,AY6,AZ6,BA6,BB6,BC6,BD6,BE6,BF6,BG6,BH6,BI6) -> 8845387729654476289932025236482674659689934758423378483578279 | BL6: =CONCATENATE(A6,B6,C6,D6,E6,F6,G6,H6,I6,J6,K6,L6,M6,N6,O6,P6,Q6,R6,S6,T6,U6,V6,W6,X6,Y6,Z6,AA6,AB6,AC6,AD6,AE6,AF6,AG6,AH6,AI6,AJ6,AK6,AL6,AM6,AN6,AO6,AP6,AQ6,AR6,AS6,AT6,AU6,AV6,AW6,AX6,AY6,AZ6,BA6,BB6,BC6,BD6) -> 88453877296544762899320252364826746596899347584233784835 | BM6: ="["&A6&","&B6&","&C6&","&D6&","&E6&","&F6&","&G6&","&H6&","&I6&","&J6&","&K6&","&L6&","&M6&","&N6&","&O6&","&P6&","&Q6&","&R6&","&S6&","&T6&","&U6&","&V6&","&W6&","&X6&","&Y6&","&Z6&","&AA6&","&AB6&","&AC6&","&AD6&","&AE6&","&AF6&","&AG6&","&AH6&","&AI6&","&AJ6&","&AK6&","&AL6&","&AM6&","&AN6&","&AO6&","&AP6&","&AQ6&","&AR6&","&AS6&","&AT6&","&AU6&","&AV6&","&AW6&","&AX6&","&AY6&","&AZ6&","&BA6&","&BB6&","&BC6&","&BD6&"]," -> [8,8,4,5,3,8,7,7,2,9,6,5,4,4,7,6,2,8,9,9,3,2,0,2,5,2,3,6,4,8,2,6,7,4,6,5,9,6,8,9,9,3,4,7,5,8,4,2,3,3,7,8,4,8,3,5], | BW6: =MOD(A6+B6,10) -> 6 | BX6: =MOD(B6+C6,10) -> 2 | BY6: =MOD(C6+D6,10) -> 9 | BZ6: =MOD(D6+E6,10) -> 8 | CA6: =MOD(E6+F6,10) -> 1 | CB6: =MOD(F6+G6,10) -> 5 | CC6: =MOD(G6+H6,10) -> 4 | CD6: =MOD(H6+I6,10) -> 9 | ... DY6: =MOD(BC6+BD6,10) -> 8 | DZ6: ="["&BW6&","&BX6&","&BY6&","&BZ6&","&CA6&","&CB6&","&CC6&","&CD6&","&CE6&","&CF6&","&CG6&","&CH6&","&CI6&","&CJ6&","&CK6&","&CL6&","&CM6&","&CN6&","&CO6&","&CP6&","&CQ6&","&CR6&","&CS6&","&CT6&","&CU6&","&CV6&","&CW6&","&CX6&","&CY6&","&CZ6&","&DA6&","&DB6&","&DC6&","&DD6&","&DE6&","&DF6&","&DG6&","&DH6&","&DI6&","&DJ6&","&DK6&","&DL6&","&DM6&","&DN6&","&DO6&","&DP6&","&DQ6&","&DR6&","&DS6&","&DT6&","&DU6&","&DV6&","&DW6&","&DX6&","&DY6&"]," -> [6,2,9,8,1,5,4,9,1,5,1,9,8,1,3,8,0,7,8,2,5,2,2,7,7,5,9,0,2,0,8,3,1,0,1,4,5,4,7,8,2,7,1,2,3,2,6,5,6,0,5,2,2,1,8],
A7: 7 | B7: 8 | C7: 9 | D7: 2 | E7: 2 | F7: 3 | G7: 7 | H7: 1 | I7: 7 | J7: 4 | K7: 2 | L7: 5 | M7: 9 | N7: 7 | O7: 3 | P7: 6 | Q7: 9 | R7: 4 | S7: 6 | T7: 8 | U7: 3 | V7: 3 | W7: 5 | X7: 7 | Y7: 3 | Z7: 4 | AA7: 8 | AB7: 5 | AC7: 6 | AD7: 3 | AE7: 7 | AF7: 8 | AG7: 2 | AH7: 7 | AI7: 5 | AJ7: 5 | AK7: 8 | AL7: 6 | AM7: 4 | AN7: 9 | AO7: 2 | AP7: 6 | AQ7: 6 | AR7: 7 | AS7: 9 | AT7: 5 | AU7: 2 | AV7: 2 | AW7: 4 | AX7: 3 | AY7: 9 | AZ7: 7 | BA7: 9 | BB7: 8 | BC7: 2 | BD7: 2 | BE7: 7 | BF7: 3 | BG7: 7 | BH7: 1 | BI7: 4 | BK7: =CONCATENATE(A7,B7,C7,D7,E7,F7,G7,H7,I7,J7,K7,L7,M7,N7,O7,P7,Q7,R7,S7,T7,U7,V7,W7,X7,Y7,Z7,AA7,AB7,AC7,AD7,AE7,AF7,AG7,AH7,AI7,AJ7,AK7,AL7,AM7,AN7,AO7,AP7,AQ7,AR7,AS7,AT7,AU7,AV7,AW7,AX7,AY7,AZ7,BA7,BB7,BC7,BD7,BE7,BF7,BG7,BH7,BI7) -> 7892237174259736946833573485637827558649266795224397982273714 | BL7: =CONCATENATE(A7,B7,C7,D7,E7,F7,G7,H7,I7,J7,K7,L7,M7,N7,O7,P7,Q7,R7,S7,T7,U7,V7,W7,X7,Y7,Z7,AA7,AB7,AC7,AD7,AE7,AF7,AG7,AH7,AI7,AJ7,AK7,AL7,AM7,AN7,AO7,AP7,AQ7,AR7,AS7,AT7,AU7,AV7,AW7,AX7,AY7,AZ7,BA7,BB7,BC7,BD7) -> 78922371742597369468335734856378275586492667952243979822 | BM7: ="["&A7&","&B7&","&C7&","&D7&","&E7&","&F7&","&G7&","&H7&","&I7&","&J7&","&K7&","&L7&","&M7&","&N7&","&O7&","&P7&","&Q7&","&R7&","&S7&","&T7&","&U7&","&V7&","&W7&","&X7&","&Y7&","&Z7&","&AA7&","&AB7&","&AC7&","&AD7&","&AE7&","&AF7&","&AG7&","&AH7&","&AI7&","&AJ7&","&AK7&","&AL7&","&AM7&","&AN7&","&AO7&","&AP7&","&AQ7&","&AR7&","&AS7&","&AT7&","&AU7&","&AV7&","&AW7&","&AX7&","&AY7&","&AZ7&","&BA7&","&BB7&","&BC7&","&BD7&"]," -> [7,8,9,2,2,3,7,1,7,4,2,5,9,7,3,6,9,4,6,8,3,3,5,7,3,4,8,5,6,3,7,8,2,7,5,5,8,6,4,9,2,6,6,7,9,5,2,2,4,3,9,7,9,8,2,2], | BW7: =MOD(A7+B7,10) -> 5 | BX7: =MOD(B7+C7,10) -> 7 | BY7: =MOD(C7+D7,10) -> 1 | BZ7: =MOD(D7+E7,10) -> 4 | CA7: =MOD(E7+F7,10) -> 5 | CB7: =MOD(F7+G7,10) -> 0 | CC7: =MOD(G7+H7,10) -> 8 | CD7: =MOD(H7+I7,10) -> 8 | ... DY7: =MOD(BC7+BD7,10) -> 4 | DZ7: ="["&BW7&","&BX7&","&BY7&","&BZ7&","&CA7&","&CB7&","&CC7&","&CD7&","&CE7&","&CF7&","&CG7&","&CH7&","&CI7&","&CJ7&","&CK7&","&CL7&","&CM7&","&CN7&","&CO7&","&CP7&","&CQ7&","&CR7&","&CS7&","&CT7&","&CU7&","&CV7&","&CW7&","&CX7&","&CY7&","&CZ7&","&DA7&","&DB7&","&DC7&","&DD7&","&DE7&","&DF7&","&DG7&","&DH7&","&DI7&","&DJ7&","&DK7&","&DL7&","&DM7&","&DN7&","&DO7&","&DP7&","&DQ7&","&DR7&","&DS7&","&DT7&","&DU7&","&DV7&","&DW7&","&DX7&","&DY7&"]," -> [5,7,1,4,5,0,8,8,1,6,7,4,6,0,9,5,3,0,4,1,6,8,2,0,7,2,3,1,9,0,5,0,9,2,0,3,4,0,3,1,8,2,3,6,4,7,4,6,7,2,6,6,7,0,4],
A8: 7 | B8: 2 | C8: 6 | D8: 8 | E8: 8 | F8: 3 | G8: 4 | H8: 8 | I8: 3 | J8: 5 | K8: 2 | L8: 7 | M8: 6 | N8: 4 | O8: 3 | P8: 6 | Q8: 5 | R8: 3 | S8: 9 | T8: 8 | U8: 4 | V8: 7 | W8: 5 | X8: 4 | Y8: 2 | Z8: 9 | AA8: 6 | AB8: 6 | AC8: 3 | AD8: 8 | AE8: 5 | AF8: 5 | AG8: 9 | AH8: 7 | AI8: 4 | AJ8: 6 | AK8: 9 | AL8: 3 | AM8: 3 | AN8: 2 | AO8: 8 | AP8: 7 | AQ8: 9 | AR8: 9 | AS8: 5 | AT8: 6 | AU8: 2 | AV8: 4 | AW8: 4 | AX8: 5 | AY8: 7 | AZ8: 7 | BA8: 6 | BB8: 2 | BC8: 8 | BD8: 8 | BE8: 4 | BF8: 3 | BG8: 3 | BH8: 8 | BI8: 5 | BK8: =CONCATENATE(A8,B8,C8,D8,E8,F8,G8,H8,I8,J8,K8,L8,M8,N8,O8,P8,Q8,R8,S8,T8,U8,V8,W8,X8,Y8,Z8,AA8,AB8,AC8,AD8,AE8,AF8,AG8,AH8,AI8,AJ8,AK8,AL8,AM8,AN8,AO8,AP8,AQ8,AR8,AS8,AT8,AU8,AV8,AW8,AX8,AY8,AZ8,BA8,BB8,BC8,BD8,BE8,BF8,BG8,BH8,BI8) -> 7268834835276436539847542966385597469332879956244577628843385 | BL8: =CONCATENATE(A8,B8,C8,D8,E8,F8,G8,H8,I8,J8,K8,L8,M8,N8,O8,P8,Q8,R8,S8,T8,U8,V8,W8,X8,Y8,Z8,AA8,AB8,AC8,AD8,AE8,AF8,AG8,AH8,AI8,AJ8,AK8,AL8,AM8,AN8,AO8,AP8,AQ8,AR8,AS8,AT8,AU8,AV8,AW8,AX8,AY8,AZ8,BA8,BB8,BC8,BD8) -> 72688348352764365398475429663855974693328799562445776288 | BM8: ="["&A8&","&B8&","&C8&","&D8&","&E8&","&F8&","&G8&","&H8&","&I8&","&J8&","&K8&","&L8&","&M8&","&N8&","&O8&","&P8&","&Q8&","&R8&","&S8&","&T8&","&U8&","&V8&","&W8&","&X8&","&Y8&","&Z8&","&AA8&","&AB8&","&AC8&","&AD8&","&AE8&","&AF8&","&AG8&","&AH8&","&AI8&","&AJ8&","&AK8&","&AL8&","&AM8&","&AN8&","&AO8&","&AP8&","&AQ8&","&AR8&","&AS8&","&AT8&","&AU8&","&AV8&","&AW8&","&AX8&","&AY8&","&AZ8&","&BA8&","&BB8&","&BC8&","&BD8&"]," -> [7,2,6,8,8,3,4,8,3,5,2,7,6,4,3,6,5,3,9,8,4,7,5,4,2,9,6,6,3,8,5,5,9,7,4,6,9,3,3,2,8,7,9,9,5,6,2,4,4,5,7,7,6,2,8,8], | BW8: =MOD(A8+B8,10) -> 9 | BX8: =MOD(B8+C8,10) -> 8 | BY8: =MOD(C8+D8,10) -> 4 | BZ8: =MOD(D8+E8,10) -> 6 | CA8: =MOD(E8+F8,10) -> 1 | CB8: =MOD(F8+G8,10) -> 7 | CC8: =MOD(G8+H8,10) -> 2 | CD8: =MOD(H8+I8,10) -> 1 | ... DY8: =MOD(BC8+BD8,10) -> 6 | DZ8: ="["&BW8&","&BX8&","&BY8&","&BZ8&","&CA8&","&CB8&","&CC8&","&CD8&","&CE8&","&CF8&","&CG8&","&CH8&","&CI8&","&CJ8&","&CK8&","&CL8&","&CM8&","&CN8&","&CO8&","&CP8&","&CQ8&","&CR8&","&CS8&","&CT8&","&CU8&","&CV8&","&CW8&","&CX8&","&CY8&","&CZ8&","&DA8&","&DB8&","&DC8&","&DD8&","&DE8&","&DF8&","&DG8&","&DH8&","&DI8&","&DJ8&","&DK8&","&DL8&","&DM8&","&DN8&","&DO8&","&DP8&","&DQ8&","&DR8&","&DS8&","&DT8&","&DU8&","&DV8&","&DW8&","&DX8&","&DY8&"]," -> [9,8,4,6,1,7,2,1,8,7,9,3,0,7,9,1,8,2,7,2,1,2,9,6,1,5,2,9,1,3,0,4,6,1,0,5,2,6,5,0,5,6,8,4,1,8,6,8,9,2,4,3,8,0,6],
A9: 7 | B9: 8 | C9: 8 | D9: 6 | E9: 3 | F9: 9 | G9: 3 | H9: 4 | I9: 6 | J9: 8 | K9: 5 | L9: 5 | M9: 2 | N9: 7 | O9: 4 | P9: 4 | Q9: 9 | R9: 7 | S9: 6 | T9: 6 | U9: 2 | V9: 3 | W9: 5 | X9: 4 | Y9: 7 | Z9: 7 | AA9: 2 | AB9: 9 | AC9: 4 | AD9: 5 | AE9: 3 | AF9: 3 | AG9: 6 | AH9: 9 | AI9: 9 | AJ9: 8 | AK9: 4 | AL9: 2 | AM9: 8 | AN9: 7 | AO9: 3 | AP9: 8 | AQ9: 0 | AR9: 4 | AS9: 9 | AT9: 4 | AU9: 8 | AV9: 2 | AW9: 5 | AX9: 8 | AY9: 6 | AZ9: 7 | BA9: 8 | BB9: 8 | BC9: 3 | BD9: 6 | BE9: 3 | BF9: 9 | BG9: 6 | BH9: 4 | BI9: 8 | BK9: =CONCATENATE(A9,B9,C9,D9,E9,F9,G9,H9,I9,J9,K9,L9,M9,N9,O9,P9,Q9,R9,S9,T9,U9,V9,W9,X9,Y9,Z9,AA9,AB9,AC9,AD9,AE9,AF9,AG9,AH9,AI9,AJ9,AK9,AL9,AM9,AN9,AO9,AP9,AQ9,AR9,AS9,AT9,AU9,AV9,AW9,AX9,AY9,AZ9,BA9,BB9,BC9,BD9,BE9,BF9,BG9,BH9,BI9) -> 7886393468552744976623547729453369984287380494825867883639648 | BL9: =CONCATENATE(A9,B9,C9,D9,E9,F9,G9,H9,I9,J9,K9,L9,M9,N9,O9,P9,Q9,R9,S9,T9,U9,V9,W9,X9,Y9,Z9,AA9,AB9,AC9,AD9,AE9,AF9,AG9,AH9,AI9,AJ9,AK9,AL9,AM9,AN9,AO9,AP9,AQ9,AR9,AS9,AT9,AU9,AV9,AW9,AX9,AY9,AZ9,BA9,BB9,BC9,BD9) -> 78863934685527449766235477294533699842873804948258678836 | BM9: ="["&A9&","&B9&","&C9&","&D9&","&E9&","&F9&","&G9&","&H9&","&I9&","&J9&","&K9&","&L9&","&M9&","&N9&","&O9&","&P9&","&Q9&","&R9&","&S9&","&T9&","&U9&","&V9&","&W9&","&X9&","&Y9&","&Z9&","&AA9&","&AB9&","&AC9&","&AD9&","&AE9&","&AF9&","&AG9&","&AH9&","&AI9&","&AJ9&","&AK9&","&AL9&","&AM9&","&AN9&","&AO9&","&AP9&","&AQ9&","&AR9&","&AS9&","&AT9&","&AU9&","&AV9&","&AW9&","&AX9&","&AY9&","&AZ9&","&BA9&","&BB9&","&BC9&","&BD9&"]," -> [7,8,8,6,3,9,3,4,6,8,5,5,2,7,4,4,9,7,6,6,2,3,5,4,7,7,2,9,4,5,3,3,6,9,9,8,4,2,8,7,3,8,0,4,9,4,8,2,5,8,6,7,8,8,3,6], | BW9: =MOD(A9+B9,10) -> 5 | BX9: =MOD(B9+C9,10) -> 6 | BY9: =MOD(C9+D9,10) -> 4 | BZ9: =MOD(D9+E9,10) -> 9 | CA9: =MOD(E9+F9,10) -> 2 | CB9: =MOD(F9+G9,10) -> 2 | CC9: =MOD(G9+H9,10) -> 7 | CD9: =MOD(H9+I9,10) -> 0 | ... DY9: =MOD(BC9+BD9,10) -> 9 | DZ9: ="["&BW9&","&BX9&","&BY9&","&BZ9&","&CA9&","&CB9&","&CC9&","&CD9&","&CE9&","&CF9&","&CG9&","&CH9&","&CI9&","&CJ9&","&CK9&","&CL9&","&CM9&","&CN9&","&CO9&","&CP9&","&CQ9&","&CR9&","&CS9&","&CT9&","&CU9&","&CV9&","&CW9&","&CX9&","&CY9&","&CZ9&","&DA9&","&DB9&","&DC9&","&DD9&","&DE9&","&DF9&","&DG9&","&DH9&","&DI9&","&DJ9&","&DK9&","&DL9&","&DM9&","&DN9&","&DO9&","&DP9&","&DQ9&","&DR9&","&DS9&","&DT9&","&DU9&","&DV9&","&DW9&","&DX9&","&DY9&"]," -> [5,6,4,9,2,2,7,0,4,3,0,7,9,1,8,3,6,3,2,8,5,8,9,1,4,9,1,3,9,8,6,9,5,8,7,2,6,0,5,0,1,8,4,3,3,2,0,7,3,4,3,5,6,1,9],
A10: 2 | B10: 8 | C10: 6 | D10: 4 | E10: 2 | F10: 7 | G10: 7 | H10: 8 | I10: 3 | J10: 9 | K10: 5 | L10: 4 | M10: 4 | N10: 6 | O10: 7 | P10: 3 | Q10: 3 | R10: 5 | S10: 2 | T10: 9 | U10: 8 | V10: 8 | W10: 4 | X10: 3 | Y10: 6 | Z10: 9 | AA10: 1 | AB10: 9 | AC10: 5 | AD10: 9 | AE10: 6 | AF10: 7 | AG10: 5 | AH10: 6 | AI10: 3 | AJ10: 2 | AK10: 5 | AL10: 7 | AM10: 9 | AN10: 6 | AO10: 4 | AP10: 8 | AQ10: 9 | AR10: 2 | AS10: 6 | AT10: 5 | AU10: 8 | AV10: 2 | AW10: 2 | AX10: 4 | AY10: 3 | AZ10: 2 | BA10: 6 | BB10: 8 | BC10: 2 | BD10: 4 | BE10: 7 | BF10: 7 | BG10: 3 | BH10: 8 | BI10: 9 | BK10: =CONCATENATE(A10,B10,C10,D10,E10,F10,G10,H10,I10,J10,K10,L10,M10,N10,O10,P10,Q10,R10,S10,T10,U10,V10,W10,X10,Y10,Z10,AA10,AB10,AC10,AD10,AE10,AF10,AG10,AH10,AI10,AJ10,AK10,AL10,AM10,AN10,AO10,AP10,AQ10,AR10,AS10,AT10,AU10,AV10,AW10,AX10,AY10,AZ10,BA10,BB10,BC10,BD10,BE10,BF10,BG10,BH10,BI10) -> 2864277839544673352988436919596756325796489265822432682477389 | BL10: =CONCATENATE(A10,B10,C10,D10,E10,F10,G10,H10,I10,J10,K10,L10,M10,N10,O10,P10,Q10,R10,S10,T10,U10,V10,W10,X10,Y10,Z10,AA10,AB10,AC10,AD10,AE10,AF10,AG10,AH10,AI10,AJ10,AK10,AL10,AM10,AN10,AO10,AP10,AQ10,AR10,AS10,AT10,AU10,AV10,AW10,AX10,AY10,AZ10,BA10,BB10,BC10,BD10) -> 28642778395446733529884369195967563257964892658224326824 | BM10: ="["&A10&","&B10&","&C10&","&D10&","&E10&","&F10&","&G10&","&H10&","&I10&","&J10&","&K10&","&L10&","&M10&","&N10&","&O10&","&P10&","&Q10&","&R10&","&S10&","&T10&","&U10&","&V10&","&W10&","&X10&","&Y10&","&Z10&","&AA10&","&AB10&","&AC10&","&AD10&","&AE10&","&AF10&","&AG10&","&AH10&","&AI10&","&AJ10&","&AK10&","&AL10&","&AM10&","&AN10&","&AO10&","&AP10&","&AQ10&","&AR10&","&AS10&","&AT10&","&AU10&","&AV10&","&AW10&","&AX10&","&AY10&","&AZ10&","&BA10&","&BB10&","&BC10&","&BD10&"]," -> [2,8,6,4,2,7,7,8,3,9,5,4,4,6,7,3,3,5,2,9,8,8,4,3,6,9,1,9,5,9,6,7,5,6,3,2,5,7,9,6,4,8,9,2,6,5,8,2,2,4,3,2,6,8,2,4], | BW10: =MOD(A10+B10,10) -> 0 | BX10: =MOD(B10+C10,10) -> 4 | BY10: =MOD(C10+D10,10) -> 0 | BZ10: =MOD(D10+E10,10) -> 6 | CA10: =MOD(E10+F10,10) -> 9 | CB10: =MOD(F10+G10,10) -> 4 | CC10: =MOD(G10+H10,10) -> 5 | CD10: =MOD(H10+I10,10) -> 1 | ... DY10: =MOD(BC10+BD10,10) -> 6 | DZ10: ="["&BW10&","&BX10&","&BY10&","&BZ10&","&CA10&","&CB10&","&CC10&","&CD10&","&CE10&","&CF10&","&CG10&","&CH10&","&CI10&","&CJ10&","&CK10&","&CL10&","&CM10&","&CN10&","&CO10&","&CP10&","&CQ10&","&CR10&","&CS10&","&CT10&","&CU10&","&CV10&","&CW10&","&CX10&","&CY10&","&CZ10&","&DA10&","&DB10&","&DC10&","&DD10&","&DE10&","&DF10&","&DG10&","&DH10&","&DI10&","&DJ10&","&DK10&","&DL10&","&DM10&","&DN10&","&DO10&","&DP10&","&DQ10&","&DR10&","&DS10&","&DT10&","&DU10&","&DV10&","&DW10&","&DX10&","&DY10&"]," -> [0,4,0,6,9,4,5,1,2,4,9,8,0,3,0,6,8,7,1,7,6,2,7,9,5,0,0,4,4,5,3,2,1,9,5,7,2,6,5,0,2,7,1,8,1,3,0,4,6,7,5,8,4,0,6],
A11: 4 | B11: 4 | C11: 3 | D11: 5 | E11: 6 | F11: 6 | G11: 7 | H11: 3 | I11: 2 | J11: 2 | K11: 9 | L11: 8 | M11: 4 | N11: 0 | O11: 3 | P11: 4 | Q11: 8 | R11: 2 | S11: 4 | T11: 9 | U11: 7 | V11: 6 | W11: 2 | X11: 3 | Y11: 7 | Z11: 2 | AA11: 2 | AB11: 5 | AC11: 6 | AD11: 5 | AE11: 7 | AF11: 4 | AG11: 5 | AH11: 8 | AI11: 7 | AJ11: 9 | AK11: 2 | AL11: 6 | AM11: 6 | AN11: 8 | AO11: 5 | AP11: 9 | AQ11: 3 | AR11: 8 | AS11: 9 | AT11: 9 | AU11: 4 | AV11: 7 | AW11: 5 | AX11: 5 | AY11: 3 | AZ11: 4 | BA11: 3 | BB11: 4 | BC11: 6 | BD11: 5 | BE11: 7 | BF11: 6 | BG11: 2 | BH11: 3 | BI11: 2 | BK11: =CONCATENATE(A11,B11,C11,D11,E11,F11,G11,H11,I11,J11,K11,L11,M11,N11,O11,P11,Q11,R11,S11,T11,U11,V11,W11,X11,Y11,Z11,AA11,AB11,AC11,AD11,AE11,AF11,AG11,AH11,AI11,AJ11,AK11,AL11,AM11,AN11,AO11,AP11,AQ11,AR11,AS11,AT11,AU11,AV11,AW11,AX11,AY11,AZ11,BA11,BB11,BC11,BD11,BE11,BF11,BG11,BH11,BI11) -> 4435667322984034824976237225657458792668593899475534346576232 | BL11: =CONCATENATE(A11,B11,C11,D11,E11,F11,G11,H11,I11,J11,K11,L11,M11,N11,O11,P11,Q11,R11,S11,T11,U11,V11,W11,X11,Y11,Z11,AA11,AB11,AC11,AD11,AE11,AF11,AG11,AH11,AI11,AJ11,AK11,AL11,AM11,AN11,AO11,AP11,AQ11,AR11,AS11,AT11,AU11,AV11,AW11,AX11,AY11,AZ11,BA11,BB11,BC11,BD11) -> 44356673229840348249762372256574587926685938994755343465 | BM11: ="["&A11&","&B11&","&C11&","&D11&","&E11&","&F11&","&G11&","&H11&","&I11&","&J11&","&K11&","&L11&","&M11&","&N11&","&O11&","&P11&","&Q11&","&R11&","&S11&","&T11&","&U11&","&V11&","&W11&","&X11&","&Y11&","&Z11&","&AA11&","&AB11&","&AC11&","&AD11&","&AE11&","&AF11&","&AG11&","&AH11&","&AI11&","&AJ11&","&AK11&","&AL11&","&AM11&","&AN11&","&AO11&","&AP11&","&AQ11&","&AR11&","&AS11&","&AT11&","&AU11&","&AV11&","&AW11&","&AX11&","&AY11&","&AZ11&","&BA11&","&BB11&","&BC11&","&BD11&"]," -> [4,4,3,5,6,6,7,3,2,2,9,8,4,0,3,4,8,2,4,9,7,6,2,3,7,2,2,5,6,5,7,4,5,8,7,9,2,6,6,8,5,9,3,8,9,9,4,7,5,5,3,4,3,4,6,5], | BW11: =MOD(A11+B11,10) -> 8 | BX11: =MOD(B11+C11,10) -> 7 | BY11: =MOD(C11+D11,10) -> 8 | BZ11: =MOD(D11+E11,10) -> 1 | CA11: =MOD(E11+F11,10) -> 2 | CB11: =MOD(F11+G11,10) -> 3 | CC11: =MOD(G11+H11,10) -> 0 | CD11: =MOD(H11+I11,10) -> 5 | ... DY11: =MOD(BC11+BD11,10) -> 1 | DZ11: ="["&BW11&","&BX11&","&BY11&","&BZ11&","&CA11&","&CB11&","&CC11&","&CD11&","&CE11&","&CF11&","&CG11&","&CH11&","&CI11&","&CJ11&","&CK11&","&CL11&","&CM11&","&CN11&","&CO11&","&CP11&","&CQ11&","&CR11&","&CS11&","&CT11&","&CU11&","&CV11&","&CW11&","&CX11&","&CY11&","&CZ11&","&DA11&","&DB11&","&DC11&","&DD11&","&DE11&","&DF11&","&DG11&","&DH11&","&DI11&","&DJ11&","&DK11&","&DL11&","&DM11&","&DN11&","&DO11&","&DP11&","&DQ11&","&DR11&","&DS11&","&DT11&","&DU11&","&DV11&","&DW11&","&DX11&","&DY11&"]," -> [8,7,8,1,2,3,0,5,4,1,7,2,4,3,7,2,0,6,3,6,3,8,5,0,9,4,7,1,1,2,1,9,3,5,6,1,8,2,4,3,4,2,1,7,8,3,1,2,0,8,7,7,7,0,1],
A12: 2 | B12: 4 | C12: 8 | D12: 9 | E12: 7 | F12: 5 | G12: 7 | H12: 9 | I12: 5 | J12: 2 | K12: 6 | L12: 8 | M12: 3 | N12: 7 | O12: 6 | P12: 5 | Q12: 9 | R12: 2 | S12: 7 | T12: 8 | U12: 6 | V12: 9 | W12: 9 | X12: 3 | Y12: 6 | Z12: 2 | AA12: 3 | AB12: 4 | AC12: 5 | AD12: 8 | AE12: 8 | AF12: 2 | AG12: 5 | AH12: 4 | AI12: 6 | AJ12: 3 | AK12: 3 | AL12: 8 | AM12: 7 | AN12: 7 | AO12: 4 | AP12: 9 | AQ12: 6 | AR12: 4 | AS12: 7 | AT12: 2 | AU12: 8 | AV12: 5 | AW12: 5 | AX12: 3 | AY12: 9 | AZ12: 2 | BA12: 8 | BB12: 4 | BC12: 7 | BD12: 9 | BE12: 7 | BF12: 5 | BG12: 5 | BH12: 9 | BI12: 2 | BK12: =CONCATENATE(A12,B12,C12,D12,E12,F12,G12,H12,I12,J12,K12,L12,M12,N12,O12,P12,Q12,R12,S12,T12,U12,V12,W12,X12,Y12,Z12,AA12,AB12,AC12,AD12,AE12,AF12,AG12,AH12,AI12,AJ12,AK12,AL12,AM12,AN12,AO12,AP12,AQ12,AR12,AS12,AT12,AU12,AV12,AW12,AX12,AY12,AZ12,BA12,BB12,BC12,BD12,BE12,BF12,BG12,BH12,BI12) -> 2489757952683765927869936234588254633877496472855392847975592 | BL12: =CONCATENATE(A12,B12,C12,D12,E12,F12,G12,H12,I12,J12,K12,L12,M12,N12,O12,P12,Q12,R12,S12,T12,U12,V12,W12,X12,Y12,Z12,AA12,AB12,AC12,AD12,AE12,AF12,AG12,AH12,AI12,AJ12,AK12,AL12,AM12,AN12,AO12,AP12,AQ12,AR12,AS12,AT12,AU12,AV12,AW12,AX12,AY12,AZ12,BA12,BB12,BC12,BD12) -> 24897579526837659278699362345882546338774964728553928479 | BM12: ="["&A12&","&B12&","&C12&","&D12&","&E12&","&F12&","&G12&","&H12&","&I12&","&J12&","&K12&","&L12&","&M12&","&N12&","&O12&","&P12&","&Q12&","&R12&","&S12&","&T12&","&U12&","&V12&","&W12&","&X12&","&Y12&","&Z12&","&AA12&","&AB12&","&AC12&","&AD12&","&AE12&","&AF12&","&AG12&","&AH12&","&AI12&","&AJ12&","&AK12&","&AL12&","&AM12&","&AN12&","&AO12&","&AP12&","&AQ12&","&AR12&","&AS12&","&AT12&","&AU12&","&AV12&","&AW12&","&AX12&","&AY12&","&AZ12&","&BA12&","&BB12&","&BC12&","&BD12&"]," -> [2,4,8,9,7,5,7,9,5,2,6,8,3,7,6,5,9,2,7,8,6,9,9,3,6,2,3,4,5,8,8,2,5,4,6,3,3,8,7,7,4,9,6,4,7,2,8,5,5,3,9,2,8,4,7,9], | BW12: =MOD(A12+B12,10) -> 6 | BX12: =MOD(B12+C12,10) -> 2 | BY12: =MOD(C12+D12,10) -> 7 | BZ12: =MOD(D12+E12,10) -> 6 | CA12: =MOD(E12+F12,10) -> 2 | CB12: =MOD(F12+G12,10) -> 2 | CC12: =MOD(G12+H12,10) -> 6 | CD12: =MOD(H12+I12,10) -> 4 | ... DY12: =MOD(BC12+BD12,10) -> 6 | DZ12: ="["&BW12&","&BX12&","&BY12&","&BZ12&","&CA12&","&CB12&","&CC12&","&CD12&","&CE12&","&CF12&","&CG12&","&CH12&","&CI12&","&CJ12&","&CK12&","&CL12&","&CM12&","&CN12&","&CO12&","&CP12&","&CQ12&","&CR12&","&CS12&","&CT12&","&CU12&","&CV12&","&CW12&","&CX12&","&CY12&","&CZ12&","&DA12&","&DB12&","&DC12&","&DD12&","&DE12&","&DF12&","&DG12&","&DH12&","&DI12&","&DJ12&","&DK12&","&DL12&","&DM12&","&DN12&","&DO12&","&DP12&","&DQ12&","&DR12&","&DS12&","&DT12&","&DU12&","&DV12&","&DW12&","&DX12&","&DY12&"]," -> [6,2,7,6,2,2,6,4,7,8,4,1,0,3,1,4,1,9,5,4,5,8,2,9,8,5,7,9,3,6,0,7,9,0,9,6,1,5,4,1,3,5,0,1,9,0,3,0,8,2,1,0,2,1,6],
... A45: 4 | B45: 4 | C45: 9 | D45: 9 | E45: 5 | F45: 7 | G45: 3 | H45: 3 | I45: 8 | J45: 2 | K45: 6 | L45: 8 | M45: 8 | N45: 9 | O45: 2 | P45: 5 | Q45: 5 | R45: 3 | S45: 9 | T45: 8 | U45: 3 | V45: 6 | W45: 2 | X45: 2 | Y45: 3 | Z45: 4 | AA45: 7 | AB45: 9 | AC45: 3 | AD45: 5 | AE45: 8 | AF45: 7 | AG45: 7 | AH45: 6 | AI45: 5 | AJ45: 4 | AK45: 3 | AL45: 7 | AM45: 2 | AN45: 9 | AO45: 6 | AP45: 4 | AQ45: 8 | AR45: 5 | AS45: 9 | AT45: 4 | AU45: 5 | AV45: 6 | AW45: 9 | AX45: 7 | AY45: 5 | AZ45: 4 | BA45: 9 | BB45: 4 | BC45: 5 | BD45: 9 | BE45: 3 | BF45: 7 | BG45: 8 | BH45: 3 | BI45: 2 | BK45: =CONCATENATE(A45,B45,C45,D45,E45,F45,G45,H45,I45,J45,K45,L45,M45,N45,O45,P45,Q45,R45,S45,T45,U45,V45,W45,X45,Y45,Z45,AA45,AB45,AC45,AD45,AE45,AF45,AG45,AH45,AI45,AJ45,AK45,AL45,AM45,AN45,AO45,AP45,AQ45,AR45,AS45,AT45,AU45,AV45,AW45,AX45,AY45,AZ45,BA45,BB45,BC45,BD45,BE45,BF45,BG45,BH45,BI45) -> 4499573382688925539836223479358776543729648594569754945937832 | BL45: =CONCATENATE(A45,B45,C45,D45,E45,F45,G45,H45,I45,J45,K45,L45,M45,N45,O45,P45,Q45,R45,S45,T45,U45,V45,W45,X45,Y45,Z45,AA45,AB45,AC45,AD45,AE45,AF45,AG45,AH45,AI45,AJ45,AK45,AL45,AM45,AN45,AO45,AP45,AQ45,AR45,AS45,AT45,AU45,AV45,AW45,AX45,AY45,AZ45,BA45,BB45,BC45,BD45) -> 44995733826889255398362234793587765437296485945697549459 | BM45: ="["&A45&","&B45&","&C45&","&D45&","&E45&","&F45&","&G45&","&H45&","&I45&","&J45&","&K45&","&L45&","&M45&","&N45&","&O45&","&P45&","&Q45&","&R45&","&S45&","&T45&","&U45&","&V45&","&W45&","&X45&","&Y45&","&Z45&","&AA45&","&AB45&","&AC45&","&AD45&","&AE45&","&AF45&","&AG45&","&AH45&","&AI45&","&AJ45&","&AK45&","&AL45&","&AM45&","&AN45&","&AO45&","&AP45&","&AQ45&","&AR45&","&AS45&","&AT45&","&AU45&","&AV45&","&AW45&","&AX45&","&AY45&","&AZ45&","&BA45&","&BB45&","&BC45&","&BD45&"]," -> [4,4,9,9,5,7,3,3,8,2,6,8,8,9,2,5,5,3,9,8,3,6,2,2,3,4,7,9,3,5,8,7,7,6,5,4,3,7,2,9,6,4,8,5,9,4,5,6,9,7,5,4,9,4,5,9], | BW45: =MOD(A45+B45,10) -> 8 | BX45: =MOD(B45+C45,10) -> 3 | BY45: =MOD(C45+D45,10) -> 8 | BZ45: =MOD(D45+E45,10) -> 4 | CA45: =MOD(E45+F45,10) -> 2 | CB45: =MOD(F45+G45,10) -> 0 | CC45: =MOD(G45+H45,10) -> 6 | CD45: =MOD(H45+I45,10) -> 1 | ... DY45: =MOD(BC45+BD45,10) -> 4 | DZ45: ="["&BW45&","&BX45&","&BY45&","&BZ45&","&CA45&","&CB45&","&CC45&","&CD45&","&CE45&","&CF45&","&CG45&","&CH45&","&CI45&","&CJ45&","&CK45&","&CL45&","&CM45&","&CN45&","&CO45&","&CP45&","&CQ45&","&CR45&","&CS45&","&CT45&","&CU45&","&CV45&","&CW45&","&CX45&","&CY45&","&CZ45&","&DA45&","&DB45&","&DC45&","&DD45&","&DE45&","&DF45&","&DG45&","&DH45&","&DI45&","&DJ45&","&DK45&","&DL45&","&DM45&","&DN45&","&DO45&","&DP45&","&DQ45&","&DR45&","&DS45&","&DT45&","&DU45&","&DV45&","&DW45&","&DX45&","&DY45&"]," -> [8,3,8,4,2,0,6,1,0,8,4,6,7,1,7,0,8,2,7,1,9,8,4,5,7,1,6,2,8,3,5,4,3,1,9,7,0,9,1,5,0,2,3,4,3,9,1,5,6,2,9,3,3,9,4],

Sheet Guidance
A1: 1. Isi N/A jika blank
A2: 2. Isi Skipped jika skipped

Sheet Master
A1: Number | B1: Soal 1 | C1: Process 1 | D1: Answer 1 | E1: Label 1 | F1: Soal 2 | G1: Process 2 | H1: Answer 2 | I1: Label 2 | J1: Soal 3 | K1: Process 3 | L1: Answer 3 | M1: Label 3 | N1: Soal 4 | O1: Process 4 | P1: Answer 4 | Q1: Label 4 | R1: Soal 5 | S1: Process 5 | T1: Answer 5 | U1: Label 5 | V1: Soal 6 | W1: Process 6 | X1: Answer 6 | Y1: Label 6 | Z1: Soal 7 | AA1: Process 7 | AB1: Answer 7 | AC1: Label 7 | AD1: Soal 8 | AE1: Process 8 | AF1: Answer 8 | AG1: Label 8 | AH1: Soal 9 | AI1: Process 9 | AJ1: Answer 9 | AK1: Label 9 | AL1: Soal 10 | AM1: Process 10 | AN1: Answer 10 | AO1: Label 10 | AP1: Soal 11 | AQ1: Process 11 | AR1: Answer 11 | AS1: Label 11 | AT1: Soal 12 | AU1: Process 12 | AV1: Answer 12 | AW1: Label 12 | AX1: Soal 13 | AY1: Process 13 | AZ1: Answer 13 | BA1: Label 13 | BB1: Soal 14 | BC1: Process 14 | BD1: Answer 14 | BE1: Label 14 | BF1: Soal 15 | BG1: Process 15 | BH1: Answer 15 | BI1: Label 15 | BJ1: Soal 16 | BK1: Process 16 | BL1: Answer 16 | BM1: Label 16 | BN1: Soal 17 | BO1: Process 17 | BP1: Answer 17 | BQ1: Label 17 | BR1: Soal 18 | BS1: Process 18 | BT1: Answer 18 | BU1: Label 18 | BV1: Soal 19 | BW1: Process 19 | BX1: Answer 19 | BY1: Label 19 | BZ1: Soal 20 | CA1: Process 20 | CB1: Answer 20 | CC1: Label 20 | CD1: Soal 21 | CE1: Process 21 | CF1: Answer 21 | CG1: Label 21 | CH1: Soal 22 | CI1: Process 22 | CJ1: Answer 22 | CK1: Label 22 | CL1: Soal 23 | CM1: Process 23 | CN1: Answer 23 | CO1: Label 23 | CP1: Soal 24 | CQ1: Process 24 | CR1: Answer 24 | CS1: Label 24 | CT1: Soal 25 | CU1: Process 25 | CV1: Answer 25 | CW1: Label 25 | CX1: Soal 26 | CY1: Process 26 | CZ1: Answer 26 | DA1: Label 26 | DB1: Soal 27 | DC1: Process 27 | DD1: Answer 27 | DE1: Label 27 | DF1: Soal 28 | DG1: Process 28 | DH1: Answer 28 | DI1: Label 28 | DJ1: Soal 29 | DK1: Process 29 | DL1: Answer 29 | DM1: Label 29 | DN1: Soal 30 | DO1: Process 30 | DP1: Answer 30 | DQ1: Label 30 | DR1: Soal 31 | DS1: Process 31 | DT1: Answer 31 | DU1: Label 31 | DV1: Soal 32 | DW1: Process 32 | DX1: Answer 32 | DY1: Label 32 | DZ1: Soal 33 | EA1: Process 33 | EB1: Answer 33 | EC1: Label 33 | ED1: Soal 34 | EE1: Process 34 | EF1: Answer 34 | EG1: Label 34 | EH1: Soal 35 | EI1: Process 35 | EJ1: Answer 35 | EK1: Label 35 | EL1: Soal 36 | EM1: Process 36 | EN1: Answer 36 | EO1: Label 36 | EP1: Soal 37 | EQ1: Process 37 | ER1: Answer 37 | ES1: Label 37 | ET1: Soal 38 | EU1: Process 38 | EV1: Answer 38 | EW1: Label 38 | EX1: Soal 39 | EY1: Process 39 | EZ1: Answer 39 | FA1: Label 39 | FB1: Soal 40 | FC1: Process 40 | FD1: Answer 40 | FE1: Label 40
A2: 56 | B2: 9 | F2: 4 | J2: 8 | N2: 4 | R2: 9 | V2: 5 | Z2: 2 | AD2: 8 | AH2: 6 | AL2: 4 | AP2: 5 | AT2: 9 | AX2: 7 | BB2: 2 | BF2: 2 | BJ2: 0 | BN2: 2 | BR2: 7 | BV2: 9 | BZ2: 9 | CD2: 2 | CH2: 6 | CL2: 6 | CP2: 6 | CT2: 4 | CX2: 9 | DB2: 3 | DF2: 3 | DJ2: 8 | DN2: 9 | DR2: 8 | DV2: 4 | DZ2: 8 | ED2: 4 | EH2: 8 | EL2: 2 | EP2: 2 | ET2: 7 | EX2: 8 | FB2: 5
A3: 55 | B3: 5 | C3: =MOD(B3+B2,10) -> 4 | D3: N/A | E3: =IF(C3=D3,TRUE,IF(D3="SKIPPED","SKIPPED",IF(D3="N/A","BLANK",FALSE))) -> BLANK | F3: 4 | G3: =MOD(F3+F2,10) -> 8 | H3: N/A | I3: =IF(G3=H3,TRUE,IF(H3="SKIPPED","SKIPPED",IF(H3="N/A","BLANK",FALSE))) -> BLANK | J3: 3 | K3: =MOD(J3+J2,10) -> 1 | L3: N/A | M3: =IF(K3=L3,TRUE,IF(L3="SKIPPED","SKIPPED",IF(L3="N/A","BLANK",FALSE))) -> BLANK | N3: 3 | O3: =MOD(N3+N2,10) -> 7 | P3: N/A | Q3: =IF(O3=P3,TRUE,IF(P3="SKIPPED","SKIPPED",IF(P3="N/A","BLANK",FALSE))) -> BLANK | R3: 5 | S3: =MOD(R3+R2,10) -> 4 | T3: N/A | U3: =IF(S3=T3,TRUE,IF(T3="SKIPPED","SKIPPED",IF(T3="N/A","BLANK",FALSE))) -> BLANK | V3: 3 | W3: =MOD(V3+V2,10) -> 8 | X3: N/A | Y3: =IF(W3=X3,TRUE,IF(X3="SKIPPED","SKIPPED",IF(X3="N/A","BLANK",FALSE))) -> BLANK | Z3: 2 | AA3: =MOD(Z3+Z2,10) -> 4 | AB3: N/A | AC3: =IF(AA3=AB3,TRUE,IF(AB3="SKIPPED","SKIPPED",IF(AB3="N/A","BLANK",FALSE))) -> BLANK | AD3: 8 | AE3: =MOD(AD3+AD2,10) -> 6 | AF3: N/A | AG3: =IF(AE3=AF3,TRUE,IF(AF3="SKIPPED","SKIPPED",IF(AF3="N/A","BLANK",FALSE))) -> BLANK | AH3: 3 | AI3: =MOD(AH3+AH2,10) -> 9 | AJ3: N/A | AK3: =IF(AI3=AJ3,TRUE,IF(AJ3="SKIPPED","SKIPPED",IF(AJ3="N/A","BLANK",FALSE))) -> BLANK | AL3: 2 | AM3: =MOD(AL3+AL2,10) -> 6 | AN3: N/A | AO3: =IF(AM3=AN3,TRUE,IF(AN3="SKIPPED","SKIPPED",IF(AN3="N/A","BLANK",FALSE))) -> BLANK | AP3: 6 | AQ3: =MOD(AP3+AP2,10) -> 1 | AR3: N/A | AS3: =IF(AQ3=AR3,TRUE,IF(AR3="SKIPPED","SKIPPED",IF(AR3="N/A","BLANK",FALSE))) -> BLANK | AT3: 7 | AU3: =MOD(AT3+AT2,10) -> 6 | AV3: N/A | AW3: =IF(AU3=AV3,TRUE,IF(AV3="SKIPPED","SKIPPED",IF(AV3="N/A","BLANK",FALSE))) -> BLANK | AX3: 4 | AY3: =MOD(AX3+AX2,10) -> 1 | AZ3: N/A | BA3: =IF(AY3=AZ3,TRUE,IF(AZ3="SKIPPED","SKIPPED",IF(AZ3="N/A","BLANK",FALSE))) -> BLANK | BB3: 6 | BC3: =MOD(BB3+BB2,10) -> 8 | BD3: N/A | BE3: =IF(BC3=BD3,TRUE,IF(BD3="SKIPPED","SKIPPED",IF(BD3="N/A","BLANK",FALSE))) -> BLANK | BF3: 3 | BG3: =MOD(BF3+BF2,10) -> 5 | BH3: N/A | BI3: =IF(BG3=BH3,TRUE,IF(BH3="SKIPPED","SKIPPED",IF(BH3="N/A","BLANK",FALSE))) -> BLANK | BJ3: 8 | BK3: =MOD(BJ3+BJ2,10) -> 8 | BL3: N/A | BM3: =IF(BK3=BL3,TRUE,IF(BL3="SKIPPED","SKIPPED",IF(BL3="N/A","BLANK",FALSE))) -> BLANK | BN3: 4 | BO3: =MOD(BN3+BN2,10) -> 6 | BP3: N/A | BQ3: =IF(BO3=BP3,TRUE,IF(BP3="SKIPPED","SKIPPED",IF(BP3="N/A","BLANK",FALSE))) -> BLANK | BR3: 2 | BS3: =MOD(BR3+BR2,10) -> 9 | BT3: N/A | BU3: =IF(BS3=BT3,TRUE,IF(BT3="SKIPPED","SKIPPED",IF(BT3="N/A","BLANK",FALSE))) -> BLANK | BV3: 6 | BW3: =MOD(BV3+BV2,10) -> 5 | BX3: N/A | BY3: =IF(BW3=BX3,TRUE,IF(BX3="SKIPPED","SKIPPED",IF(BX3="N/A","BLANK",FALSE))) -> BLANK | BZ3: 5 | CA3: =MOD(BZ3+BZ2,10) -> 4 | CB3: N/A | CC3: =IF(CA3=CB3,TRUE,IF(CB3="SKIPPED","SKIPPED",IF(CB3="N/A","BLANK",FALSE))) -> BLANK | CD3: 8 | CE3: =MOD(CD3+CD2,10) -> 0 | CF3: N/A | CG3: =IF(CE3=CF3,TRUE,IF(CF3="SKIPPED","SKIPPED",IF(CF3="N/A","BLANK",FALSE))) -> BLANK | CH3: 8 | CI3: =MOD(CH3+CH2,10) -> 4 | CJ3: N/A | CK3: =IF(CI3=CJ3,TRUE,IF(CJ3="SKIPPED","SKIPPED",IF(CJ3="N/A","BLANK",FALSE))) -> BLANK | CL3: 5 | CM3: =MOD(CL3+CL2,10) -> 1 | CN3: N/A | CO3: =IF(CM3=CN3,TRUE,IF(CN3="SKIPPED","SKIPPED",IF(CN3="N/A","BLANK",FALSE))) -> BLANK | CP3: 6 | CQ3: =MOD(CP3+CP2,10) -> 2 | CR3: N/A | CS3: =IF(CQ3=CR3,TRUE,IF(CR3="SKIPPED","SKIPPED",IF(CR3="N/A","BLANK",FALSE))) -> BLANK | CT3: 8 | CU3: =MOD(CT3+CT2,10) -> 2 | CV3: N/A | CW3: =IF(CU3=CV3,TRUE,IF(CV3="SKIPPED","SKIPPED",IF(CV3="N/A","BLANK",FALSE))) -> BLANK | CX3: 3 | CY3: =MOD(CX3+CX2,10) -> 2 | CZ3: N/A | DA3: =IF(CY3=CZ3,TRUE,IF(CZ3="SKIPPED","SKIPPED",IF(CZ3="N/A","BLANK",FALSE))) -> BLANK | DB3: 9 | DC3: =MOD(DB3+DB2,10) -> 2 | DD3: N/A | DE3: =IF(DC3=DD3,TRUE,IF(DD3="SKIPPED","SKIPPED",IF(DD3="N/A","BLANK",FALSE))) -> BLANK | DF3: 7 | DG3: =MOD(DF3+DF2,10) -> 0 | DH3: N/A | DI3: =IF(DG3=DH3,TRUE,IF(DH3="SKIPPED","SKIPPED",IF(DH3="N/A","BLANK",FALSE))) -> BLANK | DJ3: 6 | DK3: =MOD(DJ3+DJ2,10) -> 4 | DL3: N/A | DM3: =IF(DK3=DL3,TRUE,IF(DL3="SKIPPED","SKIPPED",IF(DL3="N/A","BLANK",FALSE))) -> BLANK | DN3: 2 | DO3: =MOD(DN3+DN2,10) -> 1 | DP3: N/A | DQ3: =IF(DO3=DP3,TRUE,IF(DP3="SKIPPED","SKIPPED",IF(DP3="N/A","BLANK",FALSE))) -> BLANK | DR3: 6 | DS3: =MOD(DR3+DR2,10) -> 4 | DT3: N/A | DU3: =IF(DS3=DT3,TRUE,IF(DT3="SKIPPED","SKIPPED",IF(DT3="N/A","BLANK",FALSE))) -> BLANK | DV3: 3 | DW3: =MOD(DV3+DV2,10) -> 7 | DX3: N/A | DY3: =IF(DW3=DX3,TRUE,IF(DX3="SKIPPED","SKIPPED",IF(DX3="N/A","BLANK",FALSE))) -> BLANK | DZ3: 5 | EA3: =MOD(DZ3+DZ2,10) -> 3 | EB3: N/A | EC3: =IF(EA3=EB3,TRUE,IF(EB3="SKIPPED","SKIPPED",IF(EB3="N/A","BLANK",FALSE))) -> BLANK | ED3: 9 | EE3: =MOD(ED3+ED2,10) -> 3 | EF3: N/A | EG3: =IF(EE3=EF3,TRUE,IF(EF3="SKIPPED","SKIPPED",IF(EF3="N/A","BLANK",FALSE))) -> BLANK | EH3: 8 | EI3: =MOD(EH3+EH2,10) -> 6 | EJ3: N/A | EK3: =IF(EI3=EJ3,TRUE,IF(EJ3="SKIPPED","SKIPPED",IF(EJ3="N/A","BLANK",FALSE))) -> BLANK | EL3: 9 | EM3: =MOD(EL3+EL2,10) -> 1 | EN3: N/A | EO3: =IF(EM3=EN3,TRUE,IF(EN3="SKIPPED","SKIPPED",IF(EN3="N/A","BLANK",FALSE))) -> BLANK | EP3: 9 | EQ3: =MOD(EP3+EP2,10) -> 1 | ER3: N/A | ES3: =IF(EQ3=ER3,TRUE,IF(ER3="SKIPPED","SKIPPED",IF(ER3="N/A","BLANK",FALSE))) -> BLANK | ET3: 8 | EU3: =MOD(ET3+ET2,10) -> 5 | EV3: N/A | EW3: =IF(EU3=EV3,TRUE,IF(EV3="SKIPPED","SKIPPED",IF(EV3="N/A","BLANK",FALSE))) -> BLANK | EX3: 8 | EY3: =MOD(EX3+EX2,10) -> 6 | EZ3: N/A | FA3: =IF(EY3=EZ3,TRUE,IF(EZ3="SKIPPED","SKIPPED",IF(EZ3="N/A","BLANK",FALSE))) -> BLANK | FB3: 4 | FC3: =MOD(FB3+FB2,10) -> 9 | FD3: N/A | FE3: =IF(FC3=FD3,TRUE,IF(FD3="SKIPPED","SKIPPED",IF(FD3="N/A","BLANK",FALSE))) -> BLANK
A4: 54 | B4: 7 | C4: =MOD(B4+B3,10) -> 2 | D4: N/A | E4: =IF(C4=D4,TRUE,IF(D4="SKIPPED","SKIPPED",IF(D4="N/A","BLANK",FALSE))) -> BLANK | F4: 9 | G4: =MOD(F4+F3,10) -> 3 | H4: N/A | I4: =IF(G4=H4,TRUE,IF(H4="SKIPPED","SKIPPED",IF(H4="N/A","BLANK",FALSE))) -> BLANK | J4: 3 | K4: =MOD(J4+J3,10) -> 6 | L4: N/A | M4: =IF(K4=L4,TRUE,IF(L4="SKIPPED","SKIPPED",IF(L4="N/A","BLANK",FALSE))) -> BLANK | N4: 2 | O4: =MOD(N4+N3,10) -> 5 | P4: N/A | Q4: =IF(O4=P4,TRUE,IF(P4="SKIPPED","SKIPPED",IF(P4="N/A","BLANK",FALSE))) -> BLANK | R4: 2 | S4: =MOD(R4+R3,10) -> 7 | T4: N/A | U4: =IF(S4=T4,TRUE,IF(T4="SKIPPED","SKIPPED",IF(T4="N/A","BLANK",FALSE))) -> BLANK | V4: 8 | W4: =MOD(V4+V3,10) -> 1 | X4: N/A | Y4: =IF(W4=X4,TRUE,IF(X4="SKIPPED","SKIPPED",IF(X4="N/A","BLANK",FALSE))) -> BLANK | Z4: 8 | AA4: =MOD(Z4+Z3,10) -> 0 | AB4: N/A | AC4: =IF(AA4=AB4,TRUE,IF(AB4="SKIPPED","SKIPPED",IF(AB4="N/A","BLANK",FALSE))) -> BLANK | AD4: 2 | AE4: =MOD(AD4+AD3,10) -> 0 | AF4: N/A | AG4: =IF(AE4=AF4,TRUE,IF(AF4="SKIPPED","SKIPPED",IF(AF4="N/A","BLANK",FALSE))) -> BLANK | AH4: 8 | AI4: =MOD(AH4+AH3,10) -> 1 | AJ4: N/A | AK4: =IF(AI4=AJ4,TRUE,IF(AJ4="SKIPPED","SKIPPED",IF(AJ4="N/A","BLANK",FALSE))) -> BLANK | AL4: 8 | AM4: =MOD(AL4+AL3,10) -> 0 | AN4: N/A | AO4: =IF(AM4=AN4,TRUE,IF(AN4="SKIPPED","SKIPPED",IF(AN4="N/A","BLANK",FALSE))) -> BLANK | AP4: 4 | AQ4: =MOD(AP4+AP3,10) -> 0 | AR4: N/A | AS4: =IF(AQ4=AR4,TRUE,IF(AR4="SKIPPED","SKIPPED",IF(AR4="N/A","BLANK",FALSE))) -> BLANK | AT4: 4 | AU4: =MOD(AT4+AT3,10) -> 1 | AV4: N/A | AW4: =IF(AU4=AV4,TRUE,IF(AV4="SKIPPED","SKIPPED",IF(AV4="N/A","BLANK",FALSE))) -> BLANK | AX4: 4 | AY4: =MOD(AX4+AX3,10) -> 8 | AZ4: N/A | BA4: =IF(AY4=AZ4,TRUE,IF(AZ4="SKIPPED","SKIPPED",IF(AZ4="N/A","BLANK",FALSE))) -> BLANK | BB4: 6 | BC4: =MOD(BB4+BB3,10) -> 2 | BD4: N/A | BE4: =IF(BC4=BD4,TRUE,IF(BD4="SKIPPED","SKIPPED",IF(BD4="N/A","BLANK",FALSE))) -> BLANK | BF4: 5 | BG4: =MOD(BF4+BF3,10) -> 8 | BH4: N/A | BI4: =IF(BG4=BH4,TRUE,IF(BH4="SKIPPED","SKIPPED",IF(BH4="N/A","BLANK",FALSE))) -> BLANK | BJ4: 9 | BK4: =MOD(BJ4+BJ3,10) -> 7 | BL4: N/A | BM4: =IF(BK4=BL4,TRUE,IF(BL4="SKIPPED","SKIPPED",IF(BL4="N/A","BLANK",FALSE))) -> BLANK | BN4: 3 | BO4: =MOD(BN4+BN3,10) -> 7 | BP4: N/A | BQ4: =IF(BO4=BP4,TRUE,IF(BP4="SKIPPED","SKIPPED",IF(BP4="N/A","BLANK",FALSE))) -> BLANK | BR4: 5 | BS4: =MOD(BR4+BR3,10) -> 7 | BT4: N/A | BU4: =IF(BS4=BT4,TRUE,IF(BT4="SKIPPED","SKIPPED",IF(BT4="N/A","BLANK",FALSE))) -> BLANK | BV4: 3 | BW4: =MOD(BV4+BV3,10) -> 9 | BX4: N/A | BY4: =IF(BW4=BX4,TRUE,IF(BX4="SKIPPED","SKIPPED",IF(BX4="N/A","BLANK",FALSE))) -> BLANK | BZ4: 6 | CA4: =MOD(BZ4+BZ3,10) -> 1 | CB4: N/A | CC4: =IF(CA4=CB4,TRUE,IF(CB4="SKIPPED","SKIPPED",IF(CB4="N/A","BLANK",FALSE))) -> BLANK | CD4: 4 | CE4: =MOD(CD4+CD3,10) -> 2 | CF4: N/A | CG4: =IF(CE4=CF4,TRUE,IF(CF4="SKIPPED","SKIPPED",IF(CF4="N/A","BLANK",FALSE))) -> BLANK | CH4: 3 | CI4: =MOD(CH4+CH3,10) -> 1 | CJ4: N/A | CK4: =IF(CI4=CJ4,TRUE,IF(CJ4="SKIPPED","SKIPPED",IF(CJ4="N/A","BLANK",FALSE))) -> BLANK | CL4: 9 | CM4: =MOD(CL4+CL3,10) -> 4 | CN4: N/A | CO4: =IF(CM4=CN4,TRUE,IF(CN4="SKIPPED","SKIPPED",IF(CN4="N/A","BLANK",FALSE))) -> BLANK | CP4: 4 | CQ4: =MOD(CP4+CP3,10) -> 0 | CR4: N/A | CS4: =IF(CQ4=CR4,TRUE,IF(CR4="SKIPPED","SKIPPED",IF(CR4="N/A","BLANK",FALSE))) -> BLANK | CT4: 2 | CU4: =MOD(CT4+CT3,10) -> 0 | CV4: N/A | CW4: =IF(CU4=CV4,TRUE,IF(CV4="SKIPPED","SKIPPED",IF(CV4="N/A","BLANK",FALSE))) -> BLANK | CX4: 7 | CY4: =MOD(CX4+CX3,10) -> 0 | CZ4: N/A | DA4: =IF(CY4=CZ4,TRUE,IF(CZ4="SKIPPED","SKIPPED",IF(CZ4="N/A","BLANK",FALSE))) -> BLANK | DB4: 8 | DC4: =MOD(DB4+DB3,10) -> 7 | DD4: N/A | DE4: =IF(DC4=DD4,TRUE,IF(DD4="SKIPPED","SKIPPED",IF(DD4="N/A","BLANK",FALSE))) -> BLANK | DF4: 4 | DG4: =MOD(DF4+DF3,10) -> 1 | DH4: N/A | DI4: =IF(DG4=DH4,TRUE,IF(DH4="SKIPPED","SKIPPED",IF(DH4="N/A","BLANK",FALSE))) -> BLANK | DJ4: 2 | DK4: =MOD(DJ4+DJ3,10) -> 8 | DL4: N/A | DM4: =IF(DK4=DL4,TRUE,IF(DL4="SKIPPED","SKIPPED",IF(DL4="N/A","BLANK",FALSE))) -> BLANK | DN4: 5 | DO4: =MOD(DN4+DN3,10) -> 7 | DP4: N/A | DQ4: =IF(DO4=DP4,TRUE,IF(DP4="SKIPPED","SKIPPED",IF(DP4="N/A","BLANK",FALSE))) -> BLANK | DR4: 4 | DS4: =MOD(DR4+DR3,10) -> 0 | DT4: N/A | DU4: =IF(DS4=DT4,TRUE,IF(DT4="SKIPPED","SKIPPED",IF(DT4="N/A","BLANK",FALSE))) -> BLANK | DV4: 9 | DW4: =MOD(DV4+DV3,10) -> 2 | DX4: N/A | DY4: =IF(DW4=DX4,TRUE,IF(DX4="SKIPPED","SKIPPED",IF(DX4="N/A","BLANK",FALSE))) -> BLANK | DZ4: 3 | EA4: =MOD(DZ4+DZ3,10) -> 8 | EB4: N/A | EC4: =IF(EA4=EB4,TRUE,IF(EB4="SKIPPED","SKIPPED",IF(EB4="N/A","BLANK",FALSE))) -> BLANK | ED4: 3 | EE4: =MOD(ED4+ED3,10) -> 2 | EF4: N/A | EG4: =IF(EE4=EF4,TRUE,IF(EF4="SKIPPED","SKIPPED",IF(EF4="N/A","BLANK",FALSE))) -> BLANK | EH4: 4 | EI4: =MOD(EH4+EH3,10) -> 2 | EJ4: N/A | EK4: =IF(EI4=EJ4,TRUE,IF(EJ4="SKIPPED","SKIPPED",IF(EJ4="N/A","BLANK",FALSE))) -> BLANK | EL4: 7 | EM4: =MOD(EL4+EL3,10) -> 6 | EN4: N/A | EO4: =IF(EM4=EN4,TRUE,IF(EN4="SKIPPED","SKIPPED",IF(EN4="N/A","BLANK",FALSE))) -> BLANK | EP4: 4 | EQ4: =MOD(EP4+EP3,10) -> 3 | ER4: N/A | ES4: =IF(EQ4=ER4,TRUE,IF(ER4="SKIPPED","SKIPPED",IF(ER4="N/A","BLANK",FALSE))) -> BLANK | ET4: 2 | EU4: =MOD(ET4+ET3,10) -> 0 | EV4: N/A | EW4: =IF(EU4=EV4,TRUE,IF(EV4="SKIPPED","SKIPPED",IF(EV4="N/A","BLANK",FALSE))) -> BLANK | EX4: 9 | EY4: =MOD(EX4+EX3,10) -> 7 | EZ4: N/A | FA4: =IF(EY4=EZ4,TRUE,IF(EZ4="SKIPPED","SKIPPED",IF(EZ4="N/A","BLANK",FALSE))) -> BLANK | FB4: 8 | FC4: =MOD(FB4+FB3,10) -> 2 | FD4: N/A | FE4: =IF(FC4=FD4,TRUE,IF(FD4="SKIPPED","SKIPPED",IF(FD4="N/A","BLANK",FALSE))) -> BLANK
A5: 53 | B5: 2 | C5: =MOD(B5+B4,10) -> 9 | D5: N/A | E5: =IF(C5=D5,TRUE,IF(D5="SKIPPED","SKIPPED",IF(D5="N/A","BLANK",FALSE))) -> BLANK | F5: 8 | G5: =MOD(F5+F4,10) -> 7 | H5: N/A | I5: =IF(G5=H5,TRUE,IF(H5="SKIPPED","SKIPPED",IF(H5="N/A","BLANK",FALSE))) -> BLANK | J5: 6 | K5: =MOD(J5+J4,10) -> 9 | L5: N/A | M5: =IF(K5=L5,TRUE,IF(L5="SKIPPED","SKIPPED",IF(L5="N/A","BLANK",FALSE))) -> BLANK | N5: 6 | O5: =MOD(N5+N4,10) -> 8 | P5: N/A | Q5: =IF(O5=P5,TRUE,IF(P5="SKIPPED","SKIPPED",IF(P5="N/A","BLANK",FALSE))) -> BLANK | R5: 7 | S5: =MOD(R5+R4,10) -> 9 | T5: N/A | U5: =IF(S5=T5,TRUE,IF(T5="SKIPPED","SKIPPED",IF(T5="N/A","BLANK",FALSE))) -> BLANK | V5: 4 | W5: =MOD(V5+V4,10) -> 2 | X5: N/A | Y5: =IF(W5=X5,TRUE,IF(X5="SKIPPED","SKIPPED",IF(X5="N/A","BLANK",FALSE))) -> BLANK | Z5: 9 | AA5: =MOD(Z5+Z4,10) -> 7 | AB5: N/A | AC5: =IF(AA5=AB5,TRUE,IF(AB5="SKIPPED","SKIPPED",IF(AB5="N/A","BLANK",FALSE))) -> BLANK | AD5: 6 | AE5: =MOD(AD5+AD4,10) -> 8 | AF5: N/A | AG5: =IF(AE5=AF5,TRUE,IF(AF5="SKIPPED","SKIPPED",IF(AF5="N/A","BLANK",FALSE))) -> BLANK | AH5: 8 | AI5: =MOD(AH5+AH4,10) -> 6 | AJ5: N/A | AK5: =IF(AI5=AJ5,TRUE,IF(AJ5="SKIPPED","SKIPPED",IF(AJ5="N/A","BLANK",FALSE))) -> BLANK | AL5: 6 | AM5: =MOD(AL5+AL4,10) -> 4 | AN5: N/A | AO5: =IF(AM5=AN5,TRUE,IF(AN5="SKIPPED","SKIPPED",IF(AN5="N/A","BLANK",FALSE))) -> BLANK | AP5: 3 | AQ5: =MOD(AP5+AP4,10) -> 7 | AR5: N/A | AS5: =IF(AQ5=AR5,TRUE,IF(AR5="SKIPPED","SKIPPED",IF(AR5="N/A","BLANK",FALSE))) -> BLANK | AT5: 8 | AU5: =MOD(AT5+AT4,10) -> 2 | AV5: N/A | AW5: =IF(AU5=AV5,TRUE,IF(AV5="SKIPPED","SKIPPED",IF(AV5="N/A","BLANK",FALSE))) -> BLANK | AX5: 3 | AY5: =MOD(AX5+AX4,10) -> 7 | AZ5: N/A | BA5: =IF(AY5=AZ5,TRUE,IF(AZ5="SKIPPED","SKIPPED",IF(AZ5="N/A","BLANK",FALSE))) -> BLANK | BB5: 8 | BC5: =MOD(BB5+BB4,10) -> 4 | BD5: N/A | BE5: =IF(BC5=BD5,TRUE,IF(BD5="SKIPPED","SKIPPED",IF(BD5="N/A","BLANK",FALSE))) -> BLANK | BF5: 6 | BG5: =MOD(BF5+BF4,10) -> 1 | BH5: N/A | BI5: =IF(BG5=BH5,TRUE,IF(BH5="SKIPPED","SKIPPED",IF(BH5="N/A","BLANK",FALSE))) -> BLANK | BJ5: 8 | BK5: =MOD(BJ5+BJ4,10) -> 7 | BL5: N/A | BM5: =IF(BK5=BL5,TRUE,IF(BL5="SKIPPED","SKIPPED",IF(BL5="N/A","BLANK",FALSE))) -> BLANK | BN5: 8 | BO5: =MOD(BN5+BN4,10) -> 1 | BP5: N/A | BQ5: =IF(BO5=BP5,TRUE,IF(BP5="SKIPPED","SKIPPED",IF(BP5="N/A","BLANK",FALSE))) -> BLANK | BR5: 6 | BS5: =MOD(BR5+BR4,10) -> 1 | BT5: N/A | BU5: =IF(BS5=BT5,TRUE,IF(BT5="SKIPPED","SKIPPED",IF(BT5="N/A","BLANK",FALSE))) -> BLANK | BV5: 3 | BW5: =MOD(BV5+BV4,10) -> 6 | BX5: N/A | BY5: =IF(BW5=BX5,TRUE,IF(BX5="SKIPPED","SKIPPED",IF(BX5="N/A","BLANK",FALSE))) -> BLANK | BZ5: 6 | CA5: =MOD(BZ5+BZ4,10) -> 2 | CB5: N/A | CC5: =IF(CA5=CB5,TRUE,IF(CB5="SKIPPED","SKIPPED",IF(CB5="N/A","BLANK",FALSE))) -> BLANK | CD5: 2 | CE5: =MOD(CD5+CD4,10) -> 6 | CF5: N/A | CG5: =IF(CE5=CF5,TRUE,IF(CF5="SKIPPED","SKIPPED",IF(CF5="N/A","BLANK",FALSE))) -> BLANK | CH5: 6 | CI5: =MOD(CH5+CH4,10) -> 9 | CJ5: N/A | CK5: =IF(CI5=CJ5,TRUE,IF(CJ5="SKIPPED","SKIPPED",IF(CJ5="N/A","BLANK",FALSE))) -> BLANK | CL5: 8 | CM5: =MOD(CL5+CL4,10) -> 7 | CN5: N/A | CO5: =IF(CM5=CN5,TRUE,IF(CN5="SKIPPED","SKIPPED",IF(CN5="N/A","BLANK",FALSE))) -> BLANK | CP5: 7 | CQ5: =MOD(CP5+CP4,10) -> 1 | CR5: N/A | CS5: =IF(CQ5=CR5,TRUE,IF(CR5="SKIPPED","SKIPPED",IF(CR5="N/A","BLANK",FALSE))) -> BLANK | CT5: 3 | CU5: =MOD(CT5+CT4,10) -> 5 | CV5: N/A | CW5: =IF(CU5=CV5,TRUE,IF(CV5="SKIPPED","SKIPPED",IF(CV5="N/A","BLANK",FALSE))) -> BLANK | CX5: 9 | CY5: =MOD(CX5+CX4,10) -> 6 | CZ5: N/A | DA5: =IF(CY5=CZ5,TRUE,IF(CZ5="SKIPPED","SKIPPED",IF(CZ5="N/A","BLANK",FALSE))) -> BLANK | DB5: 5 | DC5: =MOD(DB5+DB4,10) -> 3 | DD5: N/A | DE5: =IF(DC5=DD5,TRUE,IF(DD5="SKIPPED","SKIPPED",IF(DD5="N/A","BLANK",FALSE))) -> BLANK | DF5: 5 | DG5: =MOD(DF5+DF4,10) -> 9 | DH5: N/A | DI5: =IF(DG5=DH5,TRUE,IF(DH5="SKIPPED","SKIPPED",IF(DH5="N/A","BLANK",FALSE))) -> BLANK | DJ5: 8 | DK5: =MOD(DJ5+DJ4,10) -> 0 | DL5: N/A | DM5: =IF(DK5=DL5,TRUE,IF(DL5="SKIPPED","SKIPPED",IF(DL5="N/A","BLANK",FALSE))) -> BLANK | DN5: 4 | DO5: =MOD(DN5+DN4,10) -> 9 | DP5: N/A | DQ5: =IF(DO5=DP5,TRUE,IF(DP5="SKIPPED","SKIPPED",IF(DP5="N/A","BLANK",FALSE))) -> BLANK | DR5: 9 | DS5: =MOD(DR5+DR4,10) -> 3 | DT5: N/A | DU5: =IF(DS5=DT5,TRUE,IF(DT5="SKIPPED","SKIPPED",IF(DT5="N/A","BLANK",FALSE))) -> BLANK | DV5: 8 | DW5: =MOD(DV5+DV4,10) -> 7 | DX5: N/A | DY5: =IF(DW5=DX5,TRUE,IF(DX5="SKIPPED","SKIPPED",IF(DX5="N/A","BLANK",FALSE))) -> BLANK | DZ5: 3 | EA5: =MOD(DZ5+DZ4,10) -> 6 | EB5: N/A | EC5: =IF(EA5=EB5,TRUE,IF(EB5="SKIPPED","SKIPPED",IF(EB5="N/A","BLANK",FALSE))) -> BLANK | ED5: 6 | EE5: =MOD(ED5+ED4,10) -> 9 | EF5: N/A | EG5: =IF(EE5=EF5,TRUE,IF(EF5="SKIPPED","SKIPPED",IF(EF5="N/A","BLANK",FALSE))) -> BLANK | EH5: 7 | EI5: =MOD(EH5+EH4,10) -> 1 | EJ5: N/A | EK5: =IF(EI5=EJ5,TRUE,IF(EJ5="SKIPPED","SKIPPED",IF(EJ5="N/A","BLANK",FALSE))) -> BLANK | EL5: 5 | EM5: =MOD(EL5+EL4,10) -> 2 | EN5: N/A | EO5: =IF(EM5=EN5,TRUE,IF(EN5="SKIPPED","SKIPPED",IF(EN5="N/A","BLANK",FALSE))) -> BLANK | EP5: 3 | EQ5: =MOD(EP5+EP4,10) -> 7 | ER5: N/A | ES5: =IF(EQ5=ER5,TRUE,IF(ER5="SKIPPED","SKIPPED",IF(ER5="N/A","BLANK",FALSE))) -> BLANK | ET5: 2 | EU5: =MOD(ET5+ET4,10) -> 4 | EV5: N/A | EW5: =IF(EU5=EV5,TRUE,IF(EV5="SKIPPED","SKIPPED",IF(EV5="N/A","BLANK",FALSE))) -> BLANK | EX5: 2 | EY5: =MOD(EX5+EX4,10) -> 1 | EZ5: N/A | FA5: =IF(EY5=EZ5,TRUE,IF(EZ5="SKIPPED","SKIPPED",IF(EZ5="N/A","BLANK",FALSE))) -> BLANK | FB5: 8 | FC5: =MOD(FB5+FB4,10) -> 6 | FD5: N/A | FE5: =IF(FC5=FD5,TRUE,IF(FD5="SKIPPED","SKIPPED",IF(FD5="N/A","BLANK",FALSE))) -> BLANK
A6: 52 | B6: 9 | C6: =MOD(B6+B5,10) -> 1 | D6: N/A | E6: =IF(C6=D6,TRUE,IF(D6="SKIPPED","SKIPPED",IF(D6="N/A","BLANK",FALSE))) -> BLANK | F6: 9 | G6: =MOD(F6+F5,10) -> 7 | H6: N/A | I6: =IF(G6=H6,TRUE,IF(H6="SKIPPED","SKIPPED",IF(H6="N/A","BLANK",FALSE))) -> BLANK | J6: 0 | K6: =MOD(J6+J5,10) -> 6 | L6: N/A | M6: =IF(K6=L6,TRUE,IF(L6="SKIPPED","SKIPPED",IF(L6="N/A","BLANK",FALSE))) -> BLANK | N6: 4 | O6: =MOD(N6+N5,10) -> 0 | P6: N/A | Q6: =IF(O6=P6,TRUE,IF(P6="SKIPPED","SKIPPED",IF(P6="N/A","BLANK",FALSE))) -> BLANK | R6: 6 | S6: =MOD(R6+R5,10) -> 3 | T6: N/A | U6: =IF(S6=T6,TRUE,IF(T6="SKIPPED","SKIPPED",IF(T6="N/A","BLANK",FALSE))) -> BLANK | V6: 8 | W6: =MOD(V6+V5,10) -> 2 | X6: N/A | Y6: =IF(W6=X6,TRUE,IF(X6="SKIPPED","SKIPPED",IF(X6="N/A","BLANK",FALSE))) -> BLANK | Z6: 7 | AA6: =MOD(Z6+Z5,10) -> 6 | AB6: N/A | AC6: =IF(AA6=AB6,TRUE,IF(AB6="SKIPPED","SKIPPED",IF(AB6="N/A","BLANK",FALSE))) -> BLANK | AD6: 7 | AE6: =MOD(AD6+AD5,10) -> 3 | AF6: N/A | AG6: =IF(AE6=AF6,TRUE,IF(AF6="SKIPPED","SKIPPED",IF(AF6="N/A","BLANK",FALSE))) -> BLANK | AH6: 7 | AI6: =MOD(AH6+AH5,10) -> 5 | AJ6: N/A | AK6: =IF(AI6=AJ6,TRUE,IF(AJ6="SKIPPED","SKIPPED",IF(AJ6="N/A","BLANK",FALSE))) -> BLANK | AL6: 2 | AM6: =MOD(AL6+AL5,10) -> 8 | AN6: N/A | AO6: =IF(AM6=AN6,TRUE,IF(AN6="SKIPPED","SKIPPED",IF(AN6="N/A","BLANK",FALSE))) -> BLANK | AP6: 4 | AQ6: =MOD(AP6+AP5,10) -> 7 | AR6: N/A | AS6: =IF(AQ6=AR6,TRUE,IF(AR6="SKIPPED","SKIPPED",IF(AR6="N/A","BLANK",FALSE))) -> BLANK | AT6: 2 | AU6: =MOD(AT6+AT5,10) -> 0 | AV6: N/A | AW6: =IF(AU6=AV6,TRUE,IF(AV6="SKIPPED","SKIPPED",IF(AV6="N/A","BLANK",FALSE))) -> BLANK | AX6: 6 | AY6: =MOD(AX6+AX5,10) -> 9 | AZ6: N/A | BA6: =IF(AY6=AZ6,TRUE,IF(AZ6="SKIPPED","SKIPPED",IF(AZ6="N/A","BLANK",FALSE))) -> BLANK | BB6: 6 | BC6: =MOD(BB6+BB5,10) -> 4 | BD6: N/A | BE6: =IF(BC6=BD6,TRUE,IF(BD6="SKIPPED","SKIPPED",IF(BD6="N/A","BLANK",FALSE))) -> BLANK | BF6: 5 | BG6: =MOD(BF6+BF5,10) -> 1 | BH6: N/A | BI6: =IF(BG6=BH6,TRUE,IF(BH6="SKIPPED","SKIPPED",IF(BH6="N/A","BLANK",FALSE))) -> BLANK | BJ6: 2 | BK6: =MOD(BJ6+BJ5,10) -> 0 | BL6: N/A | BM6: =IF(BK6=BL6,TRUE,IF(BL6="SKIPPED","SKIPPED",IF(BL6="N/A","BLANK",FALSE))) -> BLANK | BN6: 4 | BO6: =MOD(BN6+BN5,10) -> 2 | BP6: N/A | BQ6: =IF(BO6=BP6,TRUE,IF(BP6="SKIPPED","SKIPPED",IF(BP6="N/A","BLANK",FALSE))) -> BLANK | BR6: 5 | BS6: =MOD(BR6+BR5,10) -> 1 | BT6: N/A | BU6: =IF(BS6=BT6,TRUE,IF(BT6="SKIPPED","SKIPPED",IF(BT6="N/A","BLANK",FALSE))) -> BLANK | BV6: 5 | BW6: =MOD(BV6+BV5,10) -> 8 | BX6: N/A | BY6: =IF(BW6=BX6,TRUE,IF(BX6="SKIPPED","SKIPPED",IF(BX6="N/A","BLANK",FALSE))) -> BLANK | BZ6: 7 | CA6: =MOD(BZ6+BZ5,10) -> 3 | CB6: N/A | CC6: =IF(CA6=CB6,TRUE,IF(CB6="SKIPPED","SKIPPED",IF(CB6="N/A","BLANK",FALSE))) -> BLANK | CD6: 8 | CE6: =MOD(CD6+CD5,10) -> 0 | CF6: N/A | CG6: =IF(CE6=CF6,TRUE,IF(CF6="SKIPPED","SKIPPED",IF(CF6="N/A","BLANK",FALSE))) -> BLANK | CH6: 4 | CI6: =MOD(CH6+CH5,10) -> 0 | CJ6: N/A | CK6: =IF(CI6=CJ6,TRUE,IF(CJ6="SKIPPED","SKIPPED",IF(CJ6="N/A","BLANK",FALSE))) -> BLANK | CL6: 3 | CM6: =MOD(CL6+CL5,10) -> 1 | CN6: N/A | CO6: =IF(CM6=CN6,TRUE,IF(CN6="SKIPPED","SKIPPED",IF(CN6="N/A","BLANK",FALSE))) -> BLANK | CP6: 2 | CQ6: =MOD(CP6+CP5,10) -> 9 | CR6: N/A | CS6: =IF(CQ6=CR6,TRUE,IF(CR6="SKIPPED","SKIPPED",IF(CR6="N/A","BLANK",FALSE))) -> BLANK | CT6: 4 | CU6: =MOD(CT6+CT5,10) -> 7 | CV6: N/A | CW6: =IF(CU6=CV6,TRUE,IF(CV6="SKIPPED","SKIPPED",IF(CV6="N/A","BLANK",FALSE))) -> BLANK | CX6: 9 | CY6: =MOD(CX6+CX5,10) -> 8 | CZ6: N/A | DA6: =IF(CY6=CZ6,TRUE,IF(CZ6="SKIPPED","SKIPPED",IF(CZ6="N/A","BLANK",FALSE))) -> BLANK | DB6: 7 | DC6: =MOD(DB6+DB5,10) -> 2 | DD6: N/A | DE6: =IF(DC6=DD6,TRUE,IF(DD6="SKIPPED","SKIPPED",IF(DD6="N/A","BLANK",FALSE))) -> BLANK | DF6: 9 | DG6: =MOD(DF6+DF5,10) -> 4 | DH6: N/A | DI6: =IF(DG6=DH6,TRUE,IF(DH6="SKIPPED","SKIPPED",IF(DH6="N/A","BLANK",FALSE))) -> BLANK | DJ6: 3 | DK6: =MOD(DJ6+DJ5,10) -> 1 | DL6: N/A | DM6: =IF(DK6=DL6,TRUE,IF(DL6="SKIPPED","SKIPPED",IF(DL6="N/A","BLANK",FALSE))) -> BLANK | DN6: 6 | DO6: =MOD(DN6+DN5,10) -> 0 | DP6: N/A | DQ6: =IF(DO6=DP6,TRUE,IF(DP6="SKIPPED","SKIPPED",IF(DP6="N/A","BLANK",FALSE))) -> BLANK | DR6: 4 | DS6: =MOD(DR6+DR5,10) -> 3 | DT6: N/A | DU6: =IF(DS6=DT6,TRUE,IF(DT6="SKIPPED","SKIPPED",IF(DT6="N/A","BLANK",FALSE))) -> BLANK | DV6: 5 | DW6: =MOD(DV6+DV5,10) -> 3 | DX6: N/A | DY6: =IF(DW6=DX6,TRUE,IF(DX6="SKIPPED","SKIPPED",IF(DX6="N/A","BLANK",FALSE))) -> BLANK | DZ6: 8 | EA6: =MOD(DZ6+DZ5,10) -> 1 | EB6: N/A | EC6: =IF(EA6=EB6,TRUE,IF(EB6="SKIPPED","SKIPPED",IF(EB6="N/A","BLANK",FALSE))) -> BLANK | ED6: 7 | EE6: =MOD(ED6+ED5,10) -> 3 | EF6: N/A | EG6: =IF(EE6=EF6,TRUE,IF(EF6="SKIPPED","SKIPPED",IF(EF6="N/A","BLANK",FALSE))) -> BLANK | EH6: 9 | EI6: =MOD(EH6+EH5,10) -> 6 | EJ6: N/A | EK6: =IF(EI6=EJ6,TRUE,IF(EJ6="SKIPPED","SKIPPED",IF(EJ6="N/A","BLANK",FALSE))) -> BLANK | EL6: 6 | EM6: =MOD(EL6+EL5,10) -> 1 | EN6: N/A | EO6: =IF(EM6=EN6,TRUE,IF(EN6="SKIPPED","SKIPPED",IF(EN6="N/A","BLANK",FALSE))) -> BLANK | EP6: 3 | EQ6: =MOD(EP6+EP5,10) -> 6 | ER6: N/A | ES6: =IF(EQ6=ER6,TRUE,IF(ER6="SKIPPED","SKIPPED",IF(ER6="N/A","BLANK",FALSE))) -> BLANK | ET6: 9 | EU6: =MOD(ET6+ET5,10) -> 1 | EV6: N/A | EW6: =IF(EU6=EV6,TRUE,IF(EV6="SKIPPED","SKIPPED",IF(EV6="N/A","BLANK",FALSE))) -> BLANK | EX6: 5 | EY6: =MOD(EX6+EX5,10) -> 7 | EZ6: N/A | FA6: =IF(EY6=EZ6,TRUE,IF(EZ6="SKIPPED","SKIPPED",IF(EZ6="N/A","BLANK",FALSE))) -> BLANK | FB6: 2 | FC6: =MOD(FB6+FB5,10) -> 0 | FD6: N/A | FE6: =IF(FC6=FD6,TRUE,IF(FD6="SKIPPED","SKIPPED",IF(FD6="N/A","BLANK",FALSE))) -> BLANK
